Workbook

Sheet Crudo
A2: # | B2: DNI | C2: Partido | D2: Primaria | E2: Secundaria | F2: Tecnicos | G2: No Univ | H2: Univ | I2: Maestria | J2: Doctorado | K2: Sentencias | L2: Ingresos | M2: Estudios | N2: Sentencias | O2: Ingresos | P2: Ingresos | Q2: Ingresos
A3: 1 | B3: 25331980 | C3: Ahora Nación | D3: X | E3: X | H3: X | I3: X | J3: X | L3: 350000 | M3: =+IF(D3="X",1,0)+IF(E3="X",1,0)+IF(F3="X",2,0)+IF(G3="X",2,0)+IF(H3="X",3,IF(H3="Y",1.5,0))+IF(I3="X",5,IF(I3="Y",2.5,0))+IF(J3="X",10,IF(J3="Y",5,0)) -> 20 | N3: =+IF(K3="X",1,0) -> 0 | O3: 111742 | P3: =+L3/12 -> 29166.667 | Q3: =+O3/12 -> 9311.8333
A4: =+A3+1 -> 2 | B4: 21545374 | C4: Ahora Nación | D4: X | E4: X | H4: X | L4: 111742 | M4: =+IF(D4="X",1,0)+IF(E4="X",1,0)+IF(F4="X",2,0)+IF(G4="X",2,0)+IF(H4="X",3,IF(H4="Y",1.5,0))+IF(I4="X",5,IF(I4="Y",2.5,0))+IF(J4="X",10,IF(J4="Y",5,0)) -> 5 | N4: =+IF(K4="X",1,0) -> 0 | O4: 111742 | P4: =+L4/12 -> 9311.8333 | Q4: =+O4/12 -> 9311.8333
A5: =+A4+1 -> 3 | B5: 17826805 | C5: Ahora Nación | D5: X | E5: X | H5: X | L5: 147096 | M5: =+IF(D5="X",1,0)+IF(E5="X",1,0)+IF(F5="X",2,0)+IF(G5="X",2,0)+IF(H5="X",3,IF(H5="Y",1.5,0))+IF(I5="X",5,IF(I5="Y",2.5,0))+IF(J5="X",10,IF(J5="Y",5,0)) -> 5 | N5: =+IF(K5="X",1,0) -> 0 | O5: 147096 | P5: =+L5/12 -> 12258 | Q5: =+O5/12 -> 12258
A6: =+A5+1 -> 4 | B6: 26705695 | C6: Ahora Nación | D6: X | E6: X | H6: X | I6: X | L6: 110787 | M6: =+IF(D6="X",1,0)+IF(E6="X",1,0)+IF(F6="X",2,0)+IF(G6="X",2,0)+IF(H6="X",3,IF(H6="Y",1.5,0))+IF(I6="X",5,IF(I6="Y",2.5,0))+IF(J6="X",10,IF(J6="Y",5,0)) -> 10 | N6: =+IF(K6="X",1,0) -> 0 | O6: 110787 | P6: =+L6/12 -> 9232.25 | Q6: =+O6/12 -> 9232.25
A7: =+A6+1 -> 5 | B7: 07755878 | C7: Ahora Nación | D7: X | E7: X | H7: X | I7: X | L7: 217445 | M7: =+IF(D7="X",1,0)+IF(E7="X",1,0)+IF(F7="X",2,0)+IF(G7="X",2,0)+IF(H7="X",3,IF(H7="Y",1.5,0))+IF(I7="X",5,IF(I7="Y",2.5,0))+IF(J7="X",10,IF(J7="Y",5,0)) -> 10 | N7: =+IF(K7="X",1,0) -> 0 | O7: 217445 | P7: =+L7/12 -> 18120.417 | Q7: =+O7/12 -> 18120.417
A8: =+A7+1 -> 6 | B8: 09434755 | C8: Ahora Nación | D8: X | E8: X | H8: X | L8: 62558 | M8: =+IF(D8="X",1,0)+IF(E8="X",1,0)+IF(F8="X",2,0)+IF(G8="X",2,0)+IF(H8="X",3,IF(H8="Y",1.5,0))+IF(I8="X",5,IF(I8="Y",2.5,0))+IF(J8="X",10,IF(J8="Y",5,0)) -> 5 | N8: =+IF(K8="X",1,0) -> 0 | O8: 62558 | P8: =+L8/12 -> 5213.1667 | Q8: =+O8/12 -> 5213.1667
A9: =+A8+1 -> 7 | B9: 7250445
A10: =+A9+1 -> 8 | B10: 40204874 | C10: Ahora Nación | D10: X | E10: X | H10: X | L10: 394363 | M10: =+IF(D10="X",1,0)+IF(E10="X",1,0)+IF(F10="X",2,0)+IF(G10="X",2,0)+IF(H10="X",3,IF(H10="Y",1.5,0))+IF(I10="X",5,IF(I10="Y",2.5,0))+IF(J10="X",10,IF(J10="Y",5,0)) -> 5 | N10: =+IF(K10="X",1,0) -> 0 | P10: =+L10/12 -> 32863.583 | R10: Peru Libre
A11: =+A10+1 -> 9
A12: =+A11+1 -> 10 | B12: 40106921 | C12: Ahora Nación | D12: X | E12: X | H12: X | I12: X | L12: 90412.49 | M12: =+IF(D12="X",1,0)+IF(E12="X",1,0)+IF(F12="X",2,0)+IF(G12="X",2,0)+IF(H12="X",3,IF(H12="Y",1.5,0))+IF(I12="X",5,IF(I12="Y",2.5,0))+IF(J12="X",10,IF(J12="Y",5,0)) -> 10 | N12: =+IF(K12="X",1,0) -> 0 | O12: 90412.49 | P12: =+L12/12 -> 7534.3742 | Q12: =+O12/12 -> 7534.3742
A13: =+A12+1 -> 11 | B13: 8558627 | C13: Ahora Nación | D13: X | E13: X | H13: X | I13: X | J13: X | L13: 228837 | M13: =+IF(D13="X",1,0)+IF(E13="X",1,0)+IF(F13="X",2,0)+IF(G13="X",2,0)+IF(H13="X",3,IF(H13="Y",1.5,0))+IF(I13="X",5,IF(I13="Y",2.5,0))+IF(J13="X",10,IF(J13="Y",5,0)) -> 20 | N13: =+IF(K13="X",1,0) -> 0 | O13: 228837 | P13: =+L13/12 -> 19069.75 | Q13: =+O13/12 -> 19069.75
A14: =+A13+1 -> 12 | B14: 5293154 | C14: Ahora Nación | D14: X | E14: X | F14: X | L14: 44724 | M14: =+IF(D14="X",1,0)+IF(E14="X",1,0)+IF(F14="X",2,0)+IF(G14="X",2,0)+IF(H14="X",3,IF(H14="Y",1.5,0))+IF(I14="X",5,IF(I14="Y",2.5,0))+IF(J14="X",10,IF(J14="Y",5,0)) -> 4 | N14: =+IF(K14="X",1,0) -> 0 | O14: 44724 | P14: =+L14/12 -> 3727 | Q14: =+O14/12 -> 3727
A15: =+A14+1 -> 13 | B15: 8761632 | C15: Ahora Nación | D15: X | E15: X | H15: X | I15: X | J15: X | L15: 240000 | M15: =+IF(D15="X",1,0)+IF(E15="X",1,0)+IF(F15="X",2,0)+IF(G15="X",2,0)+IF(H15="X",3,IF(H15="Y",1.5,0))+IF(I15="X",5,IF(I15="Y",2.5,0))+IF(J15="X",10,IF(J15="Y",5,0)) -> 20 | N15: =+IF(K15="X",1,0) -> 0 | O15: 240000 | P15: =+L15/12 -> 20000 | Q15: =+O15/12 -> 20000
A16: =+A15+1 -> 14 | B16: 6272152 | C16: Ahora Nación | D16: X | E16: X | H16: X | I16: Y | L16: 128400 | M16: =+IF(D16="X",1,0)+IF(E16="X",1,0)+IF(F16="X",2,0)+IF(G16="X",2,0)+IF(H16="X",3,IF(H16="Y",1.5,0))+IF(I16="X",5,IF(I16="Y",2.5,0))+IF(J16="X",10,IF(J16="Y",5,0)) -> 7.5 | N16: =+IF(K16="X",1,0) -> 0 | O16: 128400 | P16: =+L16/12 -> 10700 | Q16: =+O16/12 -> 10700
A17: =+A16+1 -> 15 | B17: 29470620 | C17: Ahora Nación | D17: X | E17: X | L17: 49000 | M17: =+IF(D17="X",1,0)+IF(E17="X",1,0)+IF(F17="X",2,0)+IF(G17="X",2,0)+IF(H17="X",3,IF(H17="Y",1.5,0))+IF(I17="X",5,IF(I17="Y",2.5,0))+IF(J17="X",10,IF(J17="Y",5,0)) -> 2 | N17: =+IF(K17="X",1,0) -> 0 | O17: 49000 | P17: =+L17/12 -> 4083.3333 | Q17: =+O17/12 -> 4083.3333
A18: =+A17+1 -> 16 | B18: 80146948 | C18: Ahora Nación | D18: X | E18: X | G18: X | L18: 93720 | M18: =+IF(D18="X",1,0)+IF(E18="X",1,0)+IF(F18="X",2,0)+IF(G18="X",2,0)+IF(H18="X",3,IF(H18="Y",1.5,0))+IF(I18="X",5,IF(I18="Y",2.5,0))+IF(J18="X",10,IF(J18="Y",5,0)) -> 4 | N18: =+IF(K18="X",1,0) -> 0 | O18: 93720 | P18: =+L18/12 -> 7810 | Q18: =+O18/12 -> 7810
A19: =+A18+1 -> 17 | B19: 29666418 | C19: Ahora Nación | D19: X | E19: X | H19: X | L19: 44000 | M19: =+IF(D19="X",1,0)+IF(E19="X",1,0)+IF(F19="X",2,0)+IF(G19="X",2,0)+IF(H19="X",3,IF(H19="Y",1.5,0))+IF(I19="X",5,IF(I19="Y",2.5,0))+IF(J19="X",10,IF(J19="Y",5,0)) -> 5 | N19: =+IF(K19="X",1,0) -> 0 | O19: 44000 | P19: =+L19/12 -> 3666.6667 | Q19: =+O19/12 -> 3666.6667
A20: =+A19+1 -> 18 | B20: 04742579 | C20: Ahora Nación | D20: X | E20: X | F20: X | H20: X | I20: Y | L20: 18000 | M20: =+IF(D20="X",1,0)+IF(E20="X",1,0)+IF(F20="X",2,0)+IF(G20="X",2,0)+IF(H20="X",3,IF(H20="Y",1.5,0))+IF(I20="X",5,IF(I20="Y",2.5,0))+IF(J20="X",10,IF(J20="Y",5,0)) -> 9.5 | N20: =+IF(K20="X",1,0) -> 0 | O20: 18000 | P20: =+L20/12 -> 1500 | Q20: =+O20/12 -> 1500
A21: =+A20+1 -> 19 | B21: 6762849 | C21: Ahora Nación | D21: X | E21: X | L21: 36000 | M21: =+IF(D21="X",1,0)+IF(E21="X",1,0)+IF(F21="X",2,0)+IF(G21="X",2,0)+IF(H21="X",3,IF(H21="Y",1.5,0))+IF(I21="X",5,IF(I21="Y",2.5,0))+IF(J21="X",10,IF(J21="Y",5,0)) -> 2 | N21: =+IF(K21="X",1,0) -> 0 | O21: 36000 | P21: =+L21/12 -> 3000 | Q21: =+O21/12 -> 3000
A22: =+A21+1 -> 20 | B22: 7803059 | C22: Ahora Nación | D22: X | E22: X | F22: X | G22: X | I22: X | L22: 31000 | M22: =+IF(D22="X",1,0)+IF(E22="X",1,0)+IF(F22="X",2,0)+IF(G22="X",2,0)+IF(H22="X",3,IF(H22="Y",1.5,0))+IF(I22="X",5,IF(I22="Y",2.5,0))+IF(J22="X",10,IF(J22="Y",5,0)) -> 11 | N22: =+IF(K22="X",1,0) -> 0 | O22: 31000 | P22: =+L22/12 -> 2583.3333 | Q22: =+O22/12 -> 2583.3333
A23: =+A22+1 -> 21 | B23: 16767746 | C23: Ahora Nación | D23: X | E23: X | H23: X | L23: 6000 | M23: =+IF(D23="X",1,0)+IF(E23="X",1,0)+IF(F23="X",2,0)+IF(G23="X",2,0)+IF(H23="X",3,IF(H23="Y",1.5,0))+IF(I23="X",5,IF(I23="Y",2.5,0))+IF(J23="X",10,IF(J23="Y",5,0)) -> 5 | N23: =+IF(K23="X",1,0) -> 0 | O23: 6000 | P23: =+L23/12 -> 500 | Q23: =+O23/12 -> 500
A24: =+A23+1 -> 22 | B24: 16520088 | C24: Ahora Nación | D24: X | E24: X | L24: 14400 | M24: =+IF(D24="X",1,0)+IF(E24="X",1,0)+IF(F24="X",2,0)+IF(G24="X",2,0)+IF(H24="X",3,IF(H24="Y",1.5,0))+IF(I24="X",5,IF(I24="Y",2.5,0))+IF(J24="X",10,IF(J24="Y",5,0)) -> 2 | N24: =+IF(K24="X",1,0) -> 0 | O24: 14400 | P24: =+L24/12 -> 1200 | Q24: =+O24/12 -> 1200
A25: =+A24+1 -> 23 | B25: 1127044 | C25: Ahora Nación | D25: X | E25: X | H25: X | I25: X | J25: X | L25: 82800 | M25: =+IF(D25="X",1,0)+IF(E25="X",1,0)+IF(F25="X",2,0)+IF(G25="X",2,0)+IF(H25="X",3,IF(H25="Y",1.5,0))+IF(I25="X",5,IF(I25="Y",2.5,0))+IF(J25="X",10,IF(J25="Y",5,0)) -> 20 | N25: =+IF(K25="X",1,0) -> 0 | O25: 82800 | P25: =+L25/12 -> 6900 | Q25: =+O25/12 -> 6900
A26: =+A25+1 -> 24 | B26: 1149309 | C26: Ahora Nación | D26: X | E26: X | L26: 12000 | M26: =+IF(D26="X",1,0)+IF(E26="X",1,0)+IF(F26="X",2,0)+IF(G26="X",2,0)+IF(H26="X",3,IF(H26="Y",1.5,0))+IF(I26="X",5,IF(I26="Y",2.5,0))+IF(J26="X",10,IF(J26="Y",5,0)) -> 2 | N26: =+IF(K26="X",1,0) -> 0 | O26: 12000 | P26: =+L26/12 -> 1000 | Q26: =+O26/12 -> 1000
A27: =+A26+1 -> 25 | B27: 9099445 | C27: Ahora Nación | D27: X | E27: X | H27: X | I27: X | L27: 76500 | M27: =+IF(D27="X",1,0)+IF(E27="X",1,0)+IF(F27="X",2,0)+IF(G27="X",2,0)+IF(H27="X",3,IF(H27="Y",1.5,0))+IF(I27="X",5,IF(I27="Y",2.5,0))+IF(J27="X",10,IF(J27="Y",5,0)) -> 10 | N27: =+IF(K27="X",1,0) -> 0 | O27: 76500 | P27: =+L27/12 -> 6375 | Q27: =+O27/12 -> 6375
A28: =+A27+1 -> 26 | B28: 31616560 | C28: Ahora Nación | D28: X | E28: X | F28: X | L28: 8410.08 | M28: =+IF(D28="X",1,0)+IF(E28="X",1,0)+IF(F28="X",2,0)+IF(G28="X",2,0)+IF(H28="X",3,IF(H28="Y",1.5,0))+IF(I28="X",5,IF(I28="Y",2.5,0))+IF(J28="X",10,IF(J28="Y",5,0)) -> 4 | N28: =+IF(K28="X",1,0) -> 0 | O28: 8410.08 | P28: =+L28/12 -> 700.84 | Q28: =+O28/12 -> 700.84
A29: =+A28+1 -> 27 | B29: 9347247 | C29: Ahora Nación | D29: X | E29: X | F29: X | L29: 60279.44 | M29: =+IF(D29="X",1,0)+IF(E29="X",1,0)+IF(F29="X",2,0)+IF(G29="X",2,0)+IF(H29="X",3,IF(H29="Y",1.5,0))+IF(I29="X",5,IF(I29="Y",2.5,0))+IF(J29="X",10,IF(J29="Y",5,0)) -> 4 | N29: =+IF(K29="X",1,0) -> 0 | O29: 60279.44 | P29: =+L29/12 -> 5023.2867 | Q29: =+O29/12 -> 5023.2867
A30: =+A29+1 -> 28 | B30: 29285160 | C30: Ahora Nación | D30: X | E30: X | H30: X | L30: 42000 | M30: =+IF(D30="X",1,0)+IF(E30="X",1,0)+IF(F30="X",2,0)+IF(G30="X",2,0)+IF(H30="X",3,IF(H30="Y",1.5,0))+IF(I30="X",5,IF(I30="Y",2.5,0))+IF(J30="X",10,IF(J30="Y",5,0)) -> 5 | N30: =+IF(K30="X",1,0) -> 0 | O30: 42000 | P30: =+L30/12 -> 3500 | Q30: =+O30/12 -> 3500
A31: =+A30+1 -> 29 | B31: 32855132 | C31: Ahora Nación | D31: X | E31: X | H31: X | L31: 114407 | M31: =+IF(D31="X",1,0)+IF(E31="X",1,0)+IF(F31="X",2,0)+IF(G31="X",2,0)+IF(H31="X",3,IF(H31="Y",1.5,0))+IF(I31="X",5,IF(I31="Y",2.5,0))+IF(J31="X",10,IF(J31="Y",5,0)) -> 5 | N31: =+IF(K31="X",1,0) -> 0 | O31: 114407 | P31: =+L31/12 -> 9533.9167 | Q31: =+O31/12 -> 9533.9167
A32: =+A31+1 -> 30 | B32: 40318653 | C32: Ahora Nación | D32: X | E32: X | H32: X | L32: 44400 | M32: =+IF(D32="X",1,0)+IF(E32="X",1,0)+IF(F32="X",2,0)+IF(G32="X",2,0)+IF(H32="X",3,IF(H32="Y",1.5,0))+IF(I32="X",5,IF(I32="Y",2.5,0))+IF(J32="X",10,IF(J32="Y",5,0)) -> 5 | N32: =+IF(K32="X",1,0) -> 0 | O32: 44400 | P32: =+L32/12 -> 3700 | Q32: =+O32/12 -> 3700
L33: =+AVERAGE(L3:L32) -> 102117.18 | M33: =+AVERAGE(M3:M32) -> 7.75 | N33: =+SUM(N3:N32) -> 0 | O33: =+AVERAGE(O3:O32) -> 82468.889 | P33: =+AVERAGE(P3:P32) -> 8509.7649 | Q33: =+AVERAGE(Q3:Q32) -> 6872.4074 | R33: =30-COUNTBLANK(R3:R32) -> 1
L34: =+STDEV(L3:L32) -> 99923.434 | M34: =+STDEV(M3:M32) -> 5.7437567 | O34: =+STDEV(O3:O32) -> 65750.792 | P34: =+STDEV(P3:P32) -> 8326.9528 | Q34: =+STDEV(Q3:Q32) -> 5479.2327
K35: Con Cero | L35: =+COUNTIF(L3:L32,0) -> 0 | M35: =+COUNT(M3:M32) -> 28 | P35: =+COUNTIF(P3:P32,0) -> 0
A37: 1 | B37: 07845838 | C37: Renovación Popular | D37: X | E37: X | H37: X | I37: X | L37: 1897374 | M37: =+IF(D37="X",1,0)+IF(E37="X",1,0)+IF(F37="X",2,0)+IF(G37="X",2,0)+IF(H37="X",3,IF(H37="Y",1.5,0))+IF(I37="X",5,IF(I37="Y",2.5,0))+IF(J37="X",10,IF(J37="Y",5,0)) -> 10 | N37: =+IF(K37="X",1,0) -> 0 | P37: =+L37/12 -> 158114.5
A38: =+A37+1 -> 2 | B38: 08235876 | C38: Renovación Popular | D38: X | E38: X | L38: 0 | M38: =+IF(D38="X",1,0)+IF(E38="X",1,0)+IF(F38="X",2,0)+IF(G38="X",2,0)+IF(H38="X",3,IF(H38="Y",1.5,0))+IF(I38="X",5,IF(I38="Y",2.5,0))+IF(J38="X",10,IF(J38="Y",5,0)) -> 2 | N38: =+IF(K38="X",1,0) -> 0 | P38: =+L38/12 -> 0 | S38: Fuerza Popular | T38: Congresista
A39: =+A38+1 -> 3 | B39: 45209282 | C39: Renovación Popular | D39: X | E39: X | L39: 237928.72 | M39: =+IF(D39="X",1,0)+IF(E39="X",1,0)+IF(F39="X",2,0)+IF(G39="X",2,0)+IF(H39="X",3,IF(H39="Y",1.5,0))+IF(I39="X",5,IF(I39="Y",2.5,0))+IF(J39="X",10,IF(J39="Y",5,0)) -> 2 | N39: =+IF(K39="X",1,0) -> 0 | O39: 237928.72 | P39: =+L39/12 -> 19827.393 | Q39: =+O39/12 -> 19827.393 | R39: Renovación
A40: =+A39+1 -> 4 | B40: 25799622 | C40: Renovación Popular | D40: X | E40: X | H40: X | L40: 233142 | M40: =+IF(D40="X",1,0)+IF(E40="X",1,0)+IF(F40="X",2,0)+IF(G40="X",2,0)+IF(H40="X",3,IF(H40="Y",1.5,0))+IF(I40="X",5,IF(I40="Y",2.5,0))+IF(J40="X",10,IF(J40="Y",5,0)) -> 5 | N40: =+IF(K40="X",1,0) -> 0 | O40: 233142 | P40: =+L40/12 -> 19428.5 | Q40: =+O40/12 -> 19428.5 | U40: Jefa de Asesores - Congresistas
A41: =+A40+1 -> 5 | B41: 09376064 | C41: Renovación Popular | D41: X | E41: X | H41: X | I41: X | J41: X | K41: X | L41: 123028 | M41: =+IF(D41="X",1,0)+IF(E41="X",1,0)+IF(F41="X",2,0)+IF(G41="X",2,0)+IF(H41="X",3,IF(H41="Y",1.5,0))+IF(I41="X",5,IF(I41="Y",2.5,0))+IF(J41="X",10,IF(J41="Y",5,0)) -> 20 | N41: =+IF(K41="X",1,0) -> 1 | O41: 123028 | P41: =+L41/12 -> 10252.333 | Q41: =+O41/12 -> 10252.333 | S41: Peru 2000 | T41: Congresista
A42: =+A41+1 -> 6 | B42: 16429203 | C42: Renovación Popular | D42: X | E42: X | H42: X | L42: 187200 | M42: =+IF(D42="X",1,0)+IF(E42="X",1,0)+IF(F42="X",2,0)+IF(G42="X",2,0)+IF(H42="X",3,IF(H42="Y",1.5,0))+IF(I42="X",5,IF(I42="Y",2.5,0))+IF(J42="X",10,IF(J42="Y",5,0)) -> 5 | N42: =+IF(K42="X",1,0) -> 0 | O42: 187200 | P42: =+L42/12 -> 15600 | Q42: =+O42/12 -> 15600 | R42: Renovación
...

Sheet Resumen
C1: Ingresos Mensuales Totales | G1: Preparación | I1: Sentencias | K1: Ingresos Mensuales Efectivos | N1: =1130*4 -> 4520
B2: Partido | C2: Promedio | D2: Desv. Standard | E2: # con Cero | F2: # Candidatos | G2: Promedio | H2: Desv. Standard | I2: Total | J2: Porcentaje | K2: Promedio | L2: Desv. Standard | M2: # Candidatos | N2: # Cand Efec | O2: TK1 | P2: TK2 | Q2: TK3 | R2: Cong Reel
A3: 1 | B3: =INDIRECT(ADDRESS(34*(A3-1)+3,3,,,"Crudo")) -> Ahora Nación | C3: =INDIRECT(ADDRESS(34*(A3-1)+33,16,,,"Crudo")) -> 8509.7649 | D3: =INDIRECT(ADDRESS(34*(A3-1)+34,16,,,"Crudo")) -> 8326.9528 | E3: =INDIRECT(ADDRESS(34*(A3-1)+35,12,,,"Crudo")) -> 0 | F3: =+E3/M3 -> 0 | G3: =INDIRECT(ADDRESS(34*(A3-1)+33,13,,,"Crudo")) -> 7.75 | H3: =INDIRECT(ADDRESS(34*(A3-1)+34,13,,,"Crudo")) -> 5.7437567 | I3: =INDIRECT(ADDRESS(34*(A3-1)+33,14,,,"Crudo")) -> 0 | J3: =+I3/M3 -> 0 | K3: =INDIRECT(ADDRESS(34*(A3-1)+33,17,,,"Crudo")) -> 6872.4074 | L3: =INDIRECT(ADDRESS(34*(A3-1)+34,17,,,"Crudo")) -> 5479.2327 | M3: =INDIRECT(ADDRESS(34*(A3-1)+35,13,,,"Crudo")) -> 28 | N3: =+M3-E3 -> 28 | O3: =+VLOOKUP(B3,[1]RESUMEN!$A$2:$D$40,2,FALSE) -> 0.28571429 | P3: =+VLOOKUP(B3,[1]RESUMEN!$A$2:$D$40,3,FALSE) -> 0.28571429 | Q3: =+VLOOKUP(B3,[1]RESUMEN!$A$2:$D$40,4,FALSE) -> 0.27777778 | R3: =INDIRECT(ADDRESS(34*(A3-1)+33,18,,,"Crudo")) -> 1
A4: =+A3+1 -> 2 | B4: =INDIRECT(ADDRESS(34*(A4-1)+3,3,,,"Crudo")) -> Renovación Popular | C4: =INDIRECT(ADDRESS(34*(A4-1)+33,16,,,"Crudo")) -> 15310.844 | D4: =INDIRECT(ADDRESS(34*(A4-1)+34,16,,,"Crudo")) -> 29497.025 | E4: =INDIRECT(ADDRESS(34*(A4-1)+35,12,,,"Crudo")) -> 7 | F4: =+E4/M4 -> 0.24137931 | G4: =INDIRECT(ADDRESS(34*(A4-1)+33,13,,,"Crudo")) -> 6.2413793 | H4: =INDIRECT(ADDRESS(34*(A4-1)+34,13,,,"Crudo")) -> 4.7932629 | I4: =INDIRECT(ADDRESS(34*(A4-1)+33,14,,,"Crudo")) -> 5 | J4: =+I4/M4 -> 0.17241379 | K4: =INDIRECT(ADDRESS(34*(A4-1)+33,17,,,"Crudo")) -> 13614.285 | L4: =INDIRECT(ADDRESS(34*(A4-1)+34,17,,,"Crudo")) -> 10648.482 | M4: =INDIRECT(ADDRESS(34*(A4-1)+35,13,,,"Crudo")) -> 29 | N4: =+M4-E4 -> 22 | O4: =+VLOOKUP(B4,[1]RESUMEN!$A$2:$D$40,2,FALSE) -> 1 | P4: =+VLOOKUP(B4,[1]RESUMEN!$A$2:$D$40,3,FALSE) -> 0 | Q4: =+VLOOKUP(B4,[1]RESUMEN!$A$2:$D$40,4,FALSE) -> 1 | R4: =INDIRECT(ADDRESS(34*(A4-1)+33,18,,,"Crudo")) -> 2
A5: =+A4+1 -> 3 | B5: =INDIRECT(ADDRESS(34*(A5-1)+3,3,,,"Crudo")) -> Fuerza Popular | C5: =INDIRECT(ADDRESS(34*(A5-1)+33,16,,,"Crudo")) -> 16195.718 | D5: =INDIRECT(ADDRESS(34*(A5-1)+34,16,,,"Crudo")) -> 14402.227 | E5: =INDIRECT(ADDRESS(34*(A5-1)+35,12,,,"Crudo")) -> 1 | F5: =+E5/M5 -> 0.033333333 | G5: =INDIRECT(ADDRESS(34*(A5-1)+33,13,,,"Crudo")) -> 7.2833333 | H5: =INDIRECT(ADDRESS(34*(A5-1)+34,13,,,"Crudo")) -> 5.0235366 | I5: =INDIRECT(ADDRESS(34*(A5-1)+33,14,,,"Crudo")) -> 6 | J5: =+I5/M5 -> 0.2 | K5: =INDIRECT(ADDRESS(34*(A5-1)+33,17,,,"Crudo")) -> 15141.926 | L5: =INDIRECT(ADDRESS(34*(A5-1)+34,17,,,"Crudo")) -> 10657.683 | M5: =INDIRECT(ADDRESS(34*(A5-1)+35,13,,,"Crudo")) -> 30 | N5: =+M5-E5 -> 29 | O5: =+VLOOKUP(B5,[1]RESUMEN!$A$2:$D$40,2,FALSE) -> 1 | P5: =+VLOOKUP(B5,[1]RESUMEN!$A$2:$D$40,3,FALSE) -> 0 | Q5: =+VLOOKUP(B5,[1]RESUMEN!$A$2:$D$40,4,FALSE) -> 1 | R5: =INDIRECT(ADDRESS(34*(A5-1)+33,18,,,"Crudo")) -> 5
A6: =+A5+1 -> 4 | B6: =INDIRECT(ADDRESS(34*(A6-1)+3,3,,,"Crudo")) -> Alianza para el Progreso | C6: =INDIRECT(ADDRESS(34*(A6-1)+33,16,,,"Crudo")) -> 42399.07 | D6: =INDIRECT(ADDRESS(34*(A6-1)+34,16,,,"Crudo")) -> 150040.03 | E6: =INDIRECT(ADDRESS(34*(A6-1)+35,12,,,"Crudo")) -> 3 | F6: =+E6/M6 -> 0.10344828 | G6: =INDIRECT(ADDRESS(34*(A6-1)+33,13,,,"Crudo")) -> 8.6724138 | H6: =INDIRECT(ADDRESS(34*(A6-1)+34,13,,,"Crudo")) -> 5.7651599 | I6: =INDIRECT(ADDRESS(34*(A6-1)+33,14,,,"Crudo")) -> 7 | J6: =+I6/M6 -> 0.24137931 | K6: =INDIRECT(ADDRESS(34*(A6-1)+33,17,,,"Crudo")) -> 16393.701 | L6: =INDIRECT(ADDRESS(34*(A6-1)+34,17,,,"Crudo")) -> 12570.068 | M6: =INDIRECT(ADDRESS(34*(A6-1)+35,13,,,"Crudo")) -> 29 | N6: =+M6-E6 -> 26 | O6: =+VLOOKUP(B6,[1]RESUMEN!$A$2:$D$40,2,FALSE) -> 1 | P6: =+VLOOKUP(B6,[1]RESUMEN!$A$2:$D$40,3,FALSE) -> 0 | Q6: =+VLOOKUP(B6,[1]RESUMEN!$A$2:$D$40,4,FALSE) -> 1 | R6: =INDIRECT(ADDRESS(34*(A6-1)+33,18,,,"Crudo")) -> 4
A7: =+A6+1 -> 5 | B7: =INDIRECT(ADDRESS(34*(A7-1)+3,3,,,"Crudo")) -> Juntos por el Perú | C7: =INDIRECT(ADDRESS(34*(A7-1)+33,16,,,"Crudo")) -> 8226.7181 | D7: =INDIRECT(ADDRESS(34*(A7-1)+34,16,,,"Crudo")) -> 16506.917 | E7: =INDIRECT(ADDRESS(34*(A7-1)+35,12,,,"Crudo")) -> 8 | F7: =+E7/M7 -> 0.26666667 | G7: =INDIRECT(ADDRESS(34*(A7-1)+33,13,,,"Crudo")) -> 5 | H7: =INDIRECT(ADDRESS(34*(A7-1)+34,13,,,"Crudo")) -> 3.8506605 | I7: =INDIRECT(ADDRESS(34*(A7-1)+33,14,,,"Crudo")) -> 2 | J7: =+I7/M7 -> 0.066666667 | K7: =INDIRECT(ADDRESS(34*(A7-1)+33,17,,,"Crudo")) -> 7985.3433 | L7: =INDIRECT(ADDRESS(34*(A7-1)+34,17,,,"Crudo")) -> 10804.794 | M7: =INDIRECT(ADDRESS(34*(A7-1)+35,13,,,"Crudo")) -> 30 | N7: =+M7-E7 -> 22 | O7: =+VLOOKUP(B7,[1]RESUMEN!$A$2:$D$40,2,FALSE) -> 1 | P7: =+VLOOKUP(B7,[1]RESUMEN!$A$2:$D$40,3,FALSE) -> 0 | Q7: =+VLOOKUP(B7,[1]RESUMEN!$A$2:$D$40,4,FALSE) -> 1 | R7: =INDIRECT(ADDRESS(34*(A7-1)+33,18,,,"Crudo")) -> 4
A8: =+A7+1 -> 6 | B8: =INDIRECT(ADDRESS(34*(A8-1)+3,3,,,"Crudo")) -> Buen Gobierno | C8: =INDIRECT(ADDRESS(34*(A8-1)+33,16,,,"Crudo")) -> 6373.2589 | D8: =INDIRECT(ADDRESS(34*(A8-1)+34,16,,,"Crudo")) -> 8562.9171 | E8: =INDIRECT(ADDRESS(34*(A8-1)+35,12,,,"Crudo")) -> 2 | F8: =+E8/M8 -> 0.066666667 | G8: =INDIRECT(ADDRESS(34*(A8-1)+33,13,,,"Crudo")) -> 6.1666667 | H8: =INDIRECT(ADDRESS(34*(A8-1)+34,13,,,"Crudo")) -> 3.8154254 | I8: =INDIRECT(ADDRESS(34*(A8-1)+33,14,,,"Crudo")) -> 1 | J8: =+I8/M8 -> 0.033333333 | K8: =INDIRECT(ADDRESS(34*(A8-1)+33,17,,,"Crudo")) -> 5266.158 | L8: =INDIRECT(ADDRESS(34*(A8-1)+34,17,,,"Crudo")) -> 5446.8126 | M8: =INDIRECT(ADDRESS(34*(A8-1)+35,13,,,"Crudo")) -> 30 | N8: =+M8-E8 -> 28 | O8: =+VLOOKUP(B8,[1]RESUMEN!$A$2:$D$40,2,FALSE) -> 0.16666667 | P8: =+VLOOKUP(B8,[1]RESUMEN!$A$2:$D$40,3,FALSE) -> 0.16666667 | Q8: =+VLOOKUP(B8,[1]RESUMEN!$A$2:$D$40,4,FALSE) -> 0.18333333 | R8: =INDIRECT(ADDRESS(34*(A8-1)+33,18,,,"Crudo")) -> 0
A9: =+A8+1 -> 7 | B9: =INDIRECT(ADDRESS(34*(A9-1)+3,3,,,"Crudo")) -> Obras | C9: =INDIRECT(ADDRESS(34*(A9-1)+33,16,,,"Crudo")) -> 2769.8314 | D9: =INDIRECT(ADDRESS(34*(A9-1)+34,16,,,"Crudo")) -> 5039.9981 | E9: =INDIRECT(ADDRESS(34*(A9-1)+35,12,,,"Crudo")) -> 9 | F9: =+E9/M9 -> 0.3 | G9: =INDIRECT(ADDRESS(34*(A9-1)+33,13,,,"Crudo")) -> 3.7 | H9: =INDIRECT(ADDRESS(34*(A9-1)+34,13,,,"Crudo")) -> 2.2916641 | I9: =INDIRECT(ADDRESS(34*(A9-1)+33,14,,,"Crudo")) -> 2 | J9: =+I9/M9 -> 0.066666667 | K9: =INDIRECT(ADDRESS(34*(A9-1)+33,17,,,"Crudo")) -> 3308.4868 | L9: =INDIRECT(ADDRESS(34*(A9-1)+34,17,,,"Crudo")) -> 4320.5012 | M9: =INDIRECT(ADDRESS(34*(A9-1)+35,13,,,"Crudo")) -> 30 | N9: =+M9-E9 -> 21 | O9: =+VLOOKUP(B9,[1]RESUMEN!$A$2:$D$40,2,FALSE) -> 0.2 | P9: =+VLOOKUP(B9,[1]RESUMEN!$A$2:$D$40,3,FALSE) -> 0.2 | Q9: =+VLOOKUP(B9,[1]RESUMEN!$A$2:$D$40,4,FALSE) -> 0.18333333 | R9: =INDIRECT(ADDRESS(34*(A9-1)+33,18,,,"Crudo")) -> 0
A10: =+A9+1 -> 8 | B10: =INDIRECT(ADDRESS(34*(A10-1)+3,3,,,"Crudo")) -> Integridad Democrática | C10: =INDIRECT(ADDRESS(34*(A10-1)+33,16,,,"Crudo")) -> 3869.726 | D10: =INDIRECT(ADDRESS(34*(A10-1)+34,16,,,"Crudo")) -> 5453.1102 | E10: =INDIRECT(ADDRESS(34*(A10-1)+35,12,,,"Crudo")) -> 14 | F10: =+E10/M10 -> 0.46666667 | G10: =INDIRECT(ADDRESS(34*(A10-1)+33,13,,,"Crudo")) -> 7.9666667 | H10: =INDIRECT(ADDRESS(34*(A10-1)+34,13,,,"Crudo")) -> 6.0883344 | I10: =INDIRECT(ADDRESS(34*(A10-1)+33,14,,,"Crudo")) -> 0 | J10: =+I10/M10 -> 0 | K10: =INDIRECT(ADDRESS(34*(A10-1)+33,17,,,"Crudo")) -> 6195.9687 | L10: =INDIRECT(ADDRESS(34*(A10-1)+34,17,,,"Crudo")) -> 3777.0187 | M10: =INDIRECT(ADDRESS(34*(A10-1)+35,13,,,"Crudo")) -> 30 | N10: =+M10-E10 -> 16 | O10: =+VLOOKUP(B10,[1]RESUMEN!$A$2:$D$40,2,FALSE) -> 0.1 | P10: =+VLOOKUP(B10,[1]RESUMEN!$A$2:$D$40,3,FALSE) -> 0.1 | Q10: =+VLOOKUP(B10,[1]RESUMEN!$A$2:$D$40,4,FALSE) -> 0.11666667 | R10: =INDIRECT(ADDRESS(34*(A10-1)+33,18,,,"Crudo")) -> 0
A11: =+A10+1 -> 9 | B11: =INDIRECT(ADDRESS(34*(A11-1)+3,3,,,"Crudo")) -> Partido Morado | C11: =INDIRECT(ADDRESS(34*(A11-1)+33,16,,,"Crudo")) -> 8654.1486 | D11: =INDIRECT(ADDRESS(34*(A11-1)+34,16,,,"Crudo")) -> 10863.373 | E11: =INDIRECT(ADDRESS(34*(A11-1)+35,12,,,"Crudo")) -> 1 | F11: =+E11/M11 -> 0.035714286 | G11: =INDIRECT(ADDRESS(34*(A11-1)+33,13,,,"Crudo")) -> 6.5357143 | H11: =INDIRECT(ADDRESS(34*(A11-1)+34,13,,,"Crudo")) -> 3.6563708 | I11: =INDIRECT(ADDRESS(34*(A11-1)+33,14,,,"Crudo")) -> 2 | J11: =+I11/M11 -> 0.071428571 | K11: =INDIRECT(ADDRESS(34*(A11-1)+33,17,,,"Crudo")) -> 6928.5959 | L11: =INDIRECT(ADDRESS(34*(A11-1)+34,17,,,"Crudo")) -> 7778.2237 | M11: =INDIRECT(ADDRESS(34*(A11-1)+35,13,,,"Crudo")) -> 28 | N11: =+M11-E11 -> 27 | O11: =+VLOOKUP(B11,[1]RESUMEN!$A$2:$D$40,2,FALSE) -> 1 | P11: =+VLOOKUP(B11,[1]RESUMEN!$A$2:$D$40,3,FALSE) -> 0 | Q11: =+VLOOKUP(B11,[1]RESUMEN!$A$2:$D$40,4,FALSE) -> 1 | R11: =INDIRECT(ADDRESS(34*(A11-1)+33,18,,,"Crudo")) -> 0
A12: =+A11+1 -> 10 | B12: =INDIRECT(ADDRESS(34*(A12-1)+3,3,,,"Crudo")) -> Cooperación Popular | C12: =INDIRECT(ADDRESS(34*(A12-1)+33,16,,,"Crudo")) -> 3355.8839 | D12: =INDIRECT(ADDRESS(34*(A12-1)+34,16,,,"Crudo")) -> 6460.0595 | E12: =INDIRECT(ADDRESS(34*(A12-1)+35,12,,,"Crudo")) -> 0 | F12: =+E12/M12 -> 0 | G12: =INDIRECT(ADDRESS(34*(A12-1)+33,13,,,"Crudo")) -> 3.4285714 | H12: =INDIRECT(ADDRESS(34*(A12-1)+34,13,,,"Crudo")) -> 3.2366944 | I12: =INDIRECT(ADDRESS(34*(A12-1)+33,14,,,"Crudo")) -> 1 | J12: =+I12/M12 -> 0.035714286 | K12: =INDIRECT(ADDRESS(34*(A12-1)+33,17,,,"Crudo")) -> 1885.5772 | L12: =INDIRECT(ADDRESS(34*(A12-1)+34,17,,,"Crudo")) -> 1651.3348 | M12: =INDIRECT(ADDRESS(34*(A12-1)+35,13,,,"Crudo")) -> 28 | N12: =+M12-E12 -> 28 | O12: =+VLOOKUP(B12,[1]RESUMEN!$A$2:$D$40,2,FALSE) -> 0.21428571 | P12: =+VLOOKUP(B12,[1]RESUMEN!$A$2:$D$40,3,FALSE) -> 0.21428571 | Q12: =+VLOOKUP(B12,[1]RESUMEN!$A$2:$D$40,4,FALSE) -> 0.29090909 | R12: =INDIRECT(ADDRESS(34*(A12-1)+33,18,,,"Crudo")) -> 1
A13: =+A12+1 -> 11 | B13: =INDIRECT(ADDRESS(34*(A13-1)+3,3,,,"Crudo")) -> Unido Perú | C13: =INDIRECT(ADDRESS(34*(A13-1)+33,16,,,"Crudo")) -> 4439.022 | D13: =INDIRECT(ADDRESS(34*(A13-1)+34,16,,,"Crudo")) -> 3820.4286 | E13: =INDIRECT(ADDRESS(34*(A13-1)+35,12,,,"Crudo")) -> 2 | F13: =+E13/M13 -> 0.11111111 | G13: =INDIRECT(ADDRESS(34*(A13-1)+33,13,,,"Crudo")) -> 8.9166667 | H13: =INDIRECT(ADDRESS(34*(A13-1)+34,13,,,"Crudo")) -> 7.0549315 | I13: =INDIRECT(ADDRESS(34*(A13-1)+33,14,,,"Crudo")) -> 2 | J13: =+I13/M13 -> 0.11111111 | K13: =INDIRECT(ADDRESS(34*(A13-1)+33,17,,,"Crudo")) -> 4105.0597 | L13: =INDIRECT(ADDRESS(34*(A13-1)+34,17,,,"Crudo")) -> 2638.2567 | M13: =INDIRECT(ADDRESS(34*(A13-1)+35,13,,,"Crudo")) -> 18 | N13: =+M13-E13 -> 16 | O13: =+VLOOKUP(B13,[1]RESUMEN!$A$2:$D$40,2,FALSE) -> 0.33333333 | P13: =+VLOOKUP(B13,[1]RESUMEN!$A$2:$D$40,3,FALSE) -> 0.33333333 | Q13: =+VLOOKUP(B13,[1]RESUMEN!$A$2:$D$40,4,FALSE) -> 0.35714286 | R13: =INDIRECT(ADDRESS(34*(A13-1)+33,18,,,"Crudo")) -> 0
A14: =+A13+1 -> 12 | B14: =INDIRECT(ADDRESS(34*(A14-1)+3,3,,,"Crudo")) -> Pais para Todos | C14: =INDIRECT(ADDRESS(34*(A14-1)+33,16,,,"Crudo")) -> 7261.4849 | D14: =INDIRECT(ADDRESS(34*(A14-1)+34,16,,,"Crudo")) -> 10930.684 | E14: =INDIRECT(ADDRESS(34*(A14-1)+35,12,,,"Crudo")) -> 5 | F14: =+E14/M14 -> 0.20833333 | G14: =INDIRECT(ADDRESS(34*(A14-1)+33,13,,,"Crudo")) -> 8.7916667 | H14: =INDIRECT(ADDRESS(34*(A14-1)+34,13,,,"Crudo")) -> 6.9967643 | I14: =INDIRECT(ADDRESS(34*(A14-1)+33,14,,,"Crudo")) -> 1 | J14: =+I14/M14 -> 0.041666667 | K14: =INDIRECT(ADDRESS(34*(A14-1)+33,17,,,"Crudo")) -> 7635.3224 | L14: =INDIRECT(ADDRESS(34*(A14-1)+34,17,,,"Crudo")) -> 7237.4904 | M14: =INDIRECT(ADDRESS(34*(A14-1)+35,13,,,"Crudo")) -> 24 | N14: =+M14-E14 -> 19 | O14: =+VLOOKUP(B14,[1]RESUMEN!$A$2:$D$40,2,FALSE) -> 0.29166667 | P14: =+VLOOKUP(B14,[1]RESUMEN!$A$2:$D$40,3,FALSE) -> 0.29166667 | Q14: =+VLOOKUP(B14,[1]RESUMEN!$A$2:$D$40,4,FALSE) -> 0.28846154 | R14: =INDIRECT(ADDRESS(34*(A14-1)+33,18,,,"Crudo")) -> 0
A15: =+A14+1 -> 13 | B15: =INDIRECT(ADDRESS(34*(A15-1)+3,3,,,"Crudo")) -> Libertad Popular | C15: =INDIRECT(ADDRESS(34*(A15-1)+33,16,,,"Crudo")) -> 9145.1448 | D15: =INDIRECT(ADDRESS(34*(A15-1)+34,16,,,"Crudo")) -> 10920.548 | E15: =INDIRECT(ADDRESS(34*(A15-1)+35,12,,,"Crudo")) -> 2 | F15: =+E15/M15 -> 0.074074074 | G15: =INDIRECT(ADDRESS(34*(A15-1)+33,13,,,"Crudo")) -> 8.2592593 | H15: =INDIRECT(ADDRESS(34*(A15-1)+34,13,,,"Crudo")) -> 6.7058677 | I15: =INDIRECT(ADDRESS(34*(A15-1)+33,14,,,"Crudo")) -> 0 | J15: =+I15/M15 -> 0 | K15: =INDIRECT(ADDRESS(34*(A15-1)+33,17,,,"Crudo")) -> 9840.3712 | L15: =INDIRECT(ADDRESS(34*(A15-1)+34,17,,,"Crudo")) -> 11266.098 | M15: =INDIRECT(ADDRESS(34*(A15-1)+35,13,,,"Crudo")) -> 27 | N15: =+M15-E15 -> 25 | O15: =+VLOOKUP(B15,[1]RESUMEN!$A$2:$D$40,2,FALSE) -> 0.14814815 | P15: =+VLOOKUP(B15,[1]RESUMEN!$A$2:$D$40,3,FALSE) -> 0.14814815 | Q15: =+VLOOKUP(B15,[1]RESUMEN!$A$2:$D$40,4,FALSE) -> 0.14035088 | R15: =INDIRECT(ADDRESS(34*(A15-1)+33,18,,,"Crudo")) -> 0
... A37: =+A36+1 -> 35 | B37: =INDIRECT(ADDRESS(34*(A37-1)+3,3,,,"Crudo")) -> Peru Libre | C37: =INDIRECT(ADDRESS(34*(A37-1)+33,16,,,"Crudo")) -> 12131.861 | D37: =INDIRECT(ADDRESS(34*(A37-1)+34,16,,,"Crudo")) -> 12582.361 | E37: =INDIRECT(ADDRESS(34*(A37-1)+35,12,,,"Crudo")) -> 1 | F37: =+E37/M37 -> 0.033333333 | G37: =INDIRECT(ADDRESS(34*(A37-1)+33,13,,,"Crudo")) -> 6.9 | H37: =INDIRECT(ADDRESS(34*(A37-1)+34,13,,,"Crudo")) -> 5.3197744 | I37: =INDIRECT(ADDRESS(34*(A37-1)+33,14,,,"Crudo")) -> 3 | J37: =+I37/M37 -> 0.1 | K37: =INDIRECT(ADDRESS(34*(A37-1)+33,17,,,"Crudo")) -> 11726.846 | L37: =INDIRECT(ADDRESS(34*(A37-1)+34,17,,,"Crudo")) -> 12000.673 | M37: =INDIRECT(ADDRESS(34*(A37-1)+35,13,,,"Crudo")) -> 30 | N37: =+M37-E37 -> 29 | O37: =+VLOOKUP(B37,[1]RESUMEN!$A$2:$D$40,2,FALSE) -> 1 | P37: =+VLOOKUP(B37,[1]RESUMEN!$A$2:$D$40,3,FALSE) -> 0 | Q37: =+VLOOKUP(B37,[1]RESUMEN!$A$2:$D$40,4,FALSE) -> 1 | R37: =INDIRECT(ADDRESS(34*(A37-1)+33,18,,,"Crudo")) -> 6
A38: =+A37+1 -> 36 | B38: Salvemos al Perú
A39: =+A38+1 -> 37 | B39: Peru Moderno
A40: =+A39+1 -> 38 | B40: CPP

Sheet Crudo2
D1: =+COUNTIF(D3:D1191,"X") -> 957 | E1: =+COUNTIF(E3:E1191,"X") -> 939 | F1: =+COUNTIF(F3:F1191,"X") -> 146 | G1: =+COUNTIF(G3:G1191,"X") -> 66 | H1: =+COUNTIF(H3:H1191,"X") -> 547 | I1: =+COUNTIF(I3:I1191,"X") -> 234 | J1: =+COUNTIF(J3:J1191,"X") -> 0 | K1: =+COUNTIF(K3:K1191,"X") -> 56
A2: # | B2: DNI | C2: Partido | D2: Primaria | E2: Secundaria | F2: Tecnicos | G2: No Univ | H2: Univ | I2: Maestria | J2: Doctorado | K2: Sentencias | L2: Ingresos | M2: Estudios | N2: Sentencias | O2: Ingresos | P2: Ingresos | Q2: Ingresos
A3: 1 | B3: 25331980 | C3: Ahora Nación | D3: X | E3: X | H3: X | I3: X | J3: X1 | L3: 350000 | M3: =+IF(D3="X",1,0)+IF(E3="X",1,0)+IF(F3="X",2,0)+IF(G3="X",2,0)+IF(H3="X",3,IF(H3="Y",1.5,0))+IF(I3="X",5,IF(I3="Y",2.5,0))+IF(J3="X1",10,IF(J3="X2",5,IF(J3="X3",3,0))) -> 20 | N3: =+IF(K3="X",1,0) -> 0 | O3: 111742 | P3: =+L3/12 -> 29166.667 | Q3: =+O3/12 -> 9311.8333
A4: =+A3+1 -> 2 | B4: 21545374 | C4: Ahora Nación | D4: X | E4: X | H4: X | L4: 111742 | M4: =+IF(D4="X",1,0)+IF(E4="X",1,0)+IF(F4="X",2,0)+IF(G4="X",2,0)+IF(H4="X",3,IF(H4="Y",1.5,0))+IF(I4="X",5,IF(I4="Y",2.5,0))+IF(J4="X1",10,IF(J4="X2",5,IF(J4="X3",3,0))) -> 5 | N4: =+IF(K4="X",1,0) -> 0 | O4: 111742 | P4: =+L4/12 -> 9311.8333 | Q4: =+O4/12 -> 9311.8333
A5: =+A4+1 -> 3 | B5: 17826805 | C5: Ahora Nación | D5: X | E5: X | H5: X | L5: 147096 | M5: =+IF(D5="X",1,0)+IF(E5="X",1,0)+IF(F5="X",2,0)+IF(G5="X",2,0)+IF(H5="X",3,IF(H5="Y",1.5,0))+IF(I5="X",5,IF(I5="Y",2.5,0))+IF(J5="X1",10,IF(J5="X2",5,IF(J5="X3",3,0))) -> 5 | N5: =+IF(K5="X",1,0) -> 0 | O5: 147096 | P5: =+L5/12 -> 12258 | Q5: =+O5/12 -> 12258
A6: =+A5+1 -> 4 | B6: 26705695 | C6: Ahora Nación | D6: X | E6: X | H6: X | I6: X | L6: 110787 | M6: =+IF(D6="X",1,0)+IF(E6="X",1,0)+IF(F6="X",2,0)+IF(G6="X",2,0)+IF(H6="X",3,IF(H6="Y",1.5,0))+IF(I6="X",5,IF(I6="Y",2.5,0))+IF(J6="X1",10,IF(J6="X2",5,IF(J6="X3",3,0))) -> 10 | N6: =+IF(K6="X",1,0) -> 0 | O6: 110787 | P6: =+L6/12 -> 9232.25 | Q6: =+O6/12 -> 9232.25
A7: =+A6+1 -> 5 | B7: 07755878 | C7: Ahora Nación | D7: X | E7: X | H7: X | I7: X | L7: 217445 | M7: =+IF(D7="X",1,0)+IF(E7="X",1,0)+IF(F7="X",2,0)+IF(G7="X",2,0)+IF(H7="X",3,IF(H7="Y",1.5,0))+IF(I7="X",5,IF(I7="Y",2.5,0))+IF(J7="X1",10,IF(J7="X2",5,IF(J7="X3",3,0))) -> 10 | N7: =+IF(K7="X",1,0) -> 0 | O7: 217445 | P7: =+L7/12 -> 18120.417 | Q7: =+O7/12 -> 18120.417
A8: =+A7+1 -> 6 | B8: 09434755 | C8: Ahora Nación | D8: X | E8: X | H8: X | L8: 62558 | M8: =+IF(D8="X",1,0)+IF(E8="X",1,0)+IF(F8="X",2,0)+IF(G8="X",2,0)+IF(H8="X",3,IF(H8="Y",1.5,0))+IF(I8="X",5,IF(I8="Y",2.5,0))+IF(J8="X1",10,IF(J8="X2",5,IF(J8="X3",3,0))) -> 5 | N8: =+IF(K8="X",1,0) -> 0 | O8: 62558 | P8: =+L8/12 -> 5213.1667 | Q8: =+O8/12 -> 5213.1667
A9: =+A8+1 -> 7 | B9: 7250445
A10: =+A9+1 -> 8 | B10: 40204874 | C10: Ahora Nación | D10: X | E10: X | H10: X | L10: 394363 | M10: =+IF(D10="X",1,0)+IF(E10="X",1,0)+IF(F10="X",2,0)+IF(G10="X",2,0)+IF(H10="X",3,IF(H10="Y",1.5,0))+IF(I10="X",5,IF(I10="Y",2.5,0))+IF(J10="X1",10,IF(J10="X2",5,IF(J10="X3",3,0))) -> 5 | N10: =+IF(K10="X",1,0) -> 0 | P10: =+L10/12 -> 32863.583 | R10: Peru Libre
A11: =+A10+1 -> 9
A12: =+A11+1 -> 10 | B12: 40106921 | C12: Ahora Nación | D12: X | E12: X | H12: X | I12: X | L12: 90412.49 | M12: =+IF(D12="X",1,0)+IF(E12="X",1,0)+IF(F12="X",2,0)+IF(G12="X",2,0)+IF(H12="X",3,IF(H12="Y",1.5,0))+IF(I12="X",5,IF(I12="Y",2.5,0))+IF(J12="X1",10,IF(J12="X2",5,IF(J12="X3",3,0))) -> 10 | N12: =+IF(K12="X",1,0) -> 0 | O12: 90412.49 | P12: =+L12/12 -> 7534.3742 | Q12: =+O12/12 -> 7534.3742
A13: =+A12+1 -> 11 | B13: 08558627 | C13: Ahora Nación | D13: X | E13: X | H13: X | I13: X | J13: X2 | L13: 228837 | M13: =+IF(D13="X",1,0)+IF(E13="X",1,0)+IF(F13="X",2,0)+IF(G13="X",2,0)+IF(H13="X",3,IF(H13="Y",1.5,0))+IF(I13="X",5,IF(I13="Y",2.5,0))+IF(J13="X1",10,IF(J13="X2",5,IF(J13="X3",3,0))) -> 15 | N13: =+IF(K13="X",1,0) -> 0 | O13: 228837 | P13: =+L13/12 -> 19069.75 | Q13: =+O13/12 -> 19069.75
A14: =+A13+1 -> 12 | B14: 5293154 | C14: Ahora Nación | D14: X | E14: X | F14: X | L14: 44724 | M14: =+IF(D14="X",1,0)+IF(E14="X",1,0)+IF(F14="X",2,0)+IF(G14="X",2,0)+IF(H14="X",3,IF(H14="Y",1.5,0))+IF(I14="X",5,IF(I14="Y",2.5,0))+IF(J14="X1",10,IF(J14="X2",5,IF(J14="X3",3,0))) -> 4 | N14: =+IF(K14="X",1,0) -> 0 | O14: 44724 | P14: =+L14/12 -> 3727 | Q14: =+O14/12 -> 3727
A15: =+A14+1 -> 13 | B15: 08761632 | C15: Ahora Nación | D15: X | E15: X | H15: X | I15: X | J15: X2 | L15: 240000 | M15: =+IF(D15="X",1,0)+IF(E15="X",1,0)+IF(F15="X",2,0)+IF(G15="X",2,0)+IF(H15="X",3,IF(H15="Y",1.5,0))+IF(I15="X",5,IF(I15="Y",2.5,0))+IF(J15="X1",10,IF(J15="X2",5,IF(J15="X3",3,0))) -> 15 | N15: =+IF(K15="X",1,0) -> 0 | O15: 240000 | P15: =+L15/12 -> 20000 | Q15: =+O15/12 -> 20000
A16: =+A15+1 -> 14 | B16: 6272152 | C16: Ahora Nación | D16: X | E16: X | H16: X | I16: X | L16: 128400 | M16: =+IF(D16="X",1,0)+IF(E16="X",1,0)+IF(F16="X",2,0)+IF(G16="X",2,0)+IF(H16="X",3,IF(H16="Y",1.5,0))+IF(I16="X",5,IF(I16="Y",2.5,0))+IF(J16="X1",10,IF(J16="X2",5,IF(J16="X3",3,0))) -> 10 | N16: =+IF(K16="X",1,0) -> 0 | O16: 128400 | P16: =+L16/12 -> 10700 | Q16: =+O16/12 -> 10700
A17: =+A16+1 -> 15 | B17: 29470620 | C17: Ahora Nación | D17: X | E17: X | L17: 49000 | M17: =+IF(D17="X",1,0)+IF(E17="X",1,0)+IF(F17="X",2,0)+IF(G17="X",2,0)+IF(H17="X",3,IF(H17="Y",1.5,0))+IF(I17="X",5,IF(I17="Y",2.5,0))+IF(J17="X1",10,IF(J17="X2",5,IF(J17="X3",3,0))) -> 2 | N17: =+IF(K17="X",1,0) -> 0 | O17: 49000 | P17: =+L17/12 -> 4083.3333 | Q17: =+O17/12 -> 4083.3333
A18: =+A17+1 -> 16 | B18: 80146948 | C18: Ahora Nación | D18: X | E18: X | G18: X | L18: 93720 | M18: =+IF(D18="X",1,0)+IF(E18="X",1,0)+IF(F18="X",2,0)+IF(G18="X",2,0)+IF(H18="X",3,IF(H18="Y",1.5,0))+IF(I18="X",5,IF(I18="Y",2.5,0))+IF(J18="X1",10,IF(J18="X2",5,IF(J18="X3",3,0))) -> 4 | N18: =+IF(K18="X",1,0) -> 0 | O18: 93720 | P18: =+L18/12 -> 7810 | Q18: =+O18/12 -> 7810
A19: =+A18+1 -> 17 | B19: 29666418 | C19: Ahora Nación | D19: X | E19: X | H19: X | L19: 44000 | M19: =+IF(D19="X",1,0)+IF(E19="X",1,0)+IF(F19="X",2,0)+IF(G19="X",2,0)+IF(H19="X",3,IF(H19="Y",1.5,0))+IF(I19="X",5,IF(I19="Y",2.5,0))+IF(J19="X1",10,IF(J19="X2",5,IF(J19="X3",3,0))) -> 5 | N19: =+IF(K19="X",1,0) -> 0 | O19: 44000 | P19: =+L19/12 -> 3666.6667 | Q19: =+O19/12 -> 3666.6667
A20: =+A19+1 -> 18 | B20: 04742579 | C20: Ahora Nación | D20: X | E20: X | F20: X | H20: X | I20: X | L20: 18000 | M20: =+IF(D20="X",1,0)+IF(E20="X",1,0)+IF(F20="X",2,0)+IF(G20="X",2,0)+IF(H20="X",3,IF(H20="Y",1.5,0))+IF(I20="X",5,IF(I20="Y",2.5,0))+IF(J20="X1",10,IF(J20="X2",5,IF(J20="X3",3,0))) -> 12 | N20: =+IF(K20="X",1,0) -> 0 | O20: 18000 | P20: =+L20/12 -> 1500 | Q20: =+O20/12 -> 1500
A21: =+A20+1 -> 19 | B21: 6762849 | C21: Ahora Nación | D21: X | E21: X | L21: 36000 | M21: =+IF(D21="X",1,0)+IF(E21="X",1,0)+IF(F21="X",2,0)+IF(G21="X",2,0)+IF(H21="X",3,IF(H21="Y",1.5,0))+IF(I21="X",5,IF(I21="Y",2.5,0))+IF(J21="X1",10,IF(J21="X2",5,IF(J21="X3",3,0))) -> 2 | N21: =+IF(K21="X",1,0) -> 0 | O21: 36000 | P21: =+L21/12 -> 3000 | Q21: =+O21/12 -> 3000
A22: =+A21+1 -> 20 | B22: 7803059 | C22: Ahora Nación | D22: X | E22: X | F22: X | G22: X | I22: X | L22: 31000 | M22: =+IF(D22="X",1,0)+IF(E22="X",1,0)+IF(F22="X",2,0)+IF(G22="X",2,0)+IF(H22="X",3,IF(H22="Y",1.5,0))+IF(I22="X",5,IF(I22="Y",2.5,0))+IF(J22="X1",10,IF(J22="X2",5,IF(J22="X3",3,0))) -> 11 | N22: =+IF(K22="X",1,0) -> 0 | O22: 31000 | P22: =+L22/12 -> 2583.3333 | Q22: =+O22/12 -> 2583.3333
A23: =+A22+1 -> 21 | B23: 16767746 | C23: Ahora Nación | D23: X | E23: X | H23: X | L23: 6000 | M23: =+IF(D23="X",1,0)+IF(E23="X",1,0)+IF(F23="X",2,0)+IF(G23="X",2,0)+IF(H23="X",3,IF(H23="Y",1.5,0))+IF(I23="X",5,IF(I23="Y",2.5,0))+IF(J23="X1",10,IF(J23="X2",5,IF(J23="X3",3,0))) -> 5 | N23: =+IF(K23="X",1,0) -> 0 | O23: 6000 | P23: =+L23/12 -> 500 | Q23: =+O23/12 -> 500
A24: =+A23+1 -> 22 | B24: 16520088 | C24: Ahora Nación | D24: X | E24: X | L24: 14400 | M24: =+IF(D24="X",1,0)+IF(E24="X",1,0)+IF(F24="X",2,0)+IF(G24="X",2,0)+IF(H24="X",3,IF(H24="Y",1.5,0))+IF(I24="X",5,IF(I24="Y",2.5,0))+IF(J24="X1",10,IF(J24="X2",5,IF(J24="X3",3,0))) -> 2 | N24: =+IF(K24="X",1,0) -> 0 | O24: 14400 | P24: =+L24/12 -> 1200 | Q24: =+O24/12 -> 1200
A25: =+A24+1 -> 23 | B25: 01127044 | C25: Ahora Nación | D25: X | E25: X | H25: X | I25: X | J25: X2 | L25: 82800 | M25: =+IF(D25="X",1,0)+IF(E25="X",1,0)+IF(F25="X",2,0)+IF(G25="X",2,0)+IF(H25="X",3,IF(H25="Y",1.5,0))+IF(I25="X",5,IF(I25="Y",2.5,0))+IF(J25="X1",10,IF(J25="X2",5,IF(J25="X3",3,0))) -> 15 | N25: =+IF(K25="X",1,0) -> 0 | O25: 82800 | P25: =+L25/12 -> 6900 | Q25: =+O25/12 -> 6900
A26: =+A25+1 -> 24 | B26: 1149309 | C26: Ahora Nación | D26: X | E26: X | L26: 12000 | M26: =+IF(D26="X",1,0)+IF(E26="X",1,0)+IF(F26="X",2,0)+IF(G26="X",2,0)+IF(H26="X",3,IF(H26="Y",1.5,0))+IF(I26="X",5,IF(I26="Y",2.5,0))+IF(J26="X1",10,IF(J26="X2",5,IF(J26="X3",3,0))) -> 2 | N26: =+IF(K26="X",1,0) -> 0 | O26: 12000 | P26: =+L26/12 -> 1000 | Q26: =+O26/12 -> 1000
A27: =+A26+1 -> 25 | B27: 9099445 | C27: Ahora Nación | D27: X | E27: X | H27: X | I27: X | L27: 76500 | M27: =+IF(D27="X",1,0)+IF(E27="X",1,0)+IF(F27="X",2,0)+IF(G27="X",2,0)+IF(H27="X",3,IF(H27="Y",1.5,0))+IF(I27="X",5,IF(I27="Y",2.5,0))+IF(J27="X1",10,IF(J27="X2",5,IF(J27="X3",3,0))) -> 10 | N27: =+IF(K27="X",1,0) -> 0 | O27: 76500 | P27: =+L27/12 -> 6375 | Q27: =+O27/12 -> 6375
A28: =+A27+1 -> 26 | B28: 31616560 | C28: Ahora Nación | D28: X | E28: X | F28: X | L28: 8410.08 | M28: =+IF(D28="X",1,0)+IF(E28="X",1,0)+IF(F28="X",2,0)+IF(G28="X",2,0)+IF(H28="X",3,IF(H28="Y",1.5,0))+IF(I28="X",5,IF(I28="Y",2.5,0))+IF(J28="X1",10,IF(J28="X2",5,IF(J28="X3",3,0))) -> 4 | N28: =+IF(K28="X",1,0) -> 0 | O28: 8410.08 | P28: =+L28/12 -> 700.84 | Q28: =+O28/12 -> 700.84
A29: =+A28+1 -> 27 | B29: 9347247 | C29: Ahora Nación | D29: X | E29: X | F29: X | L29: 60279.44 | M29: =+IF(D29="X",1,0)+IF(E29="X",1,0)+IF(F29="X",2,0)+IF(G29="X",2,0)+IF(H29="X",3,IF(H29="Y",1.5,0))+IF(I29="X",5,IF(I29="Y",2.5,0))+IF(J29="X1",10,IF(J29="X2",5,IF(J29="X3",3,0))) -> 4 | N29: =+IF(K29="X",1,0) -> 0 | O29: 60279.44 | P29: =+L29/12 -> 5023.2867 | Q29: =+O29/12 -> 5023.2867
A30: =+A29+1 -> 28 | B30: 29285160 | C30: Ahora Nación | D30: X | E30: X | H30: X | L30: 42000 | M30: =+IF(D30="X",1,0)+IF(E30="X",1,0)+IF(F30="X",2,0)+IF(G30="X",2,0)+IF(H30="X",3,IF(H30="Y",1.5,0))+IF(I30="X",5,IF(I30="Y",2.5,0))+IF(J30="X1",10,IF(J30="X2",5,IF(J30="X3",3,0))) -> 5 | N30: =+IF(K30="X",1,0) -> 0 | O30: 42000 | P30: =+L30/12 -> 3500 | Q30: =+O30/12 -> 3500
A31: =+A30+1 -> 29 | B31: 32855132 | C31: Ahora Nación | D31: X | E31: X | H31: X | L31: 114407 | M31: =+IF(D31="X",1,0)+IF(E31="X",1,0)+IF(F31="X",2,0)+IF(G31="X",2,0)+IF(H31="X",3,IF(H31="Y",1.5,0))+IF(I31="X",5,IF(I31="Y",2.5,0))+IF(J31="X1",10,IF(J31="X2",5,IF(J31="X3",3,0))) -> 5 | N31: =+IF(K31="X",1,0) -> 0 | O31: 114407 | P31: =+L31/12 -> 9533.9167 | Q31: =+O31/12 -> 9533.9167
A32: =+A31+1 -> 30 | B32: 40318653 | C32: Ahora Nación | D32: X | E32: X | H32: X | L32: 44400 | M32: =+IF(D32="X",1,0)+IF(E32="X",1,0)+IF(F32="X",2,0)+IF(G32="X",2,0)+IF(H32="X",3,IF(H32="Y",1.5,0))+IF(I32="X",5,IF(I32="Y",2.5,0))+IF(J32="X1",10,IF(J32="X2",5,IF(J32="X3",3,0))) -> 5 | N32: =+IF(K32="X",1,0) -> 0 | O32: 44400 | P32: =+L32/12 -> 3700 | Q32: =+O32/12 -> 3700
L33: =+AVERAGE(L3:L32) -> 102117.18 | M33: =+AVERAGE(M3:M32) -> 7.3928571 | N33: =+SUM(N3:N32) -> 0 | O33: =+AVERAGE(O3:O32) -> 82468.889 | P33: =+AVERAGE(P3:P32) -> 8509.7649 | Q33: =+AVERAGE(Q3:Q32) -> 6872.4074
L34: =+STDEV(L3:L32) -> 99923.434 | M34: =+STDEV(M3:M32) -> 4.7713597 | O34: =+STDEV(O3:O32) -> 65750.792 | P34: =+STDEV(P3:P32) -> 8326.9528 | Q34: =+STDEV(Q3:Q32) -> 5479.2327
K35: Con Cero | L35: =+COUNTIF(L3:L32,0) -> 0 | M35: =+COUNT(M3:M32) -> 28 | P35: =+COUNTIF(P3:P32,0) -> 0
A37: 1 | B37: 07845838 | C37: Renovación Popular | D37: X | E37: X | H37: X | I37: X | L37: 1897374 | M37: =+IF(D37="X",1,0)+IF(E37="X",1,0)+IF(F37="X",2,0)+IF(G37="X",2,0)+IF(H37="X",3,IF(H37="Y",1.5,0))+IF(I37="X",5,IF(I37="Y",2.5,0))+IF(J37="X1",10,IF(J37="X2",5,IF(J37="X3",3,0))) -> 10 | N37: =+IF(K37="X",1,0) -> 0 | P37: =+L37/12 -> 158114.5
A38: =+A37+1 -> 2 | B38: 08235876 | C38: Renovación Popular | D38: X | E38: X | L38: 0 | M38: =+IF(D38="X",1,0)+IF(E38="X",1,0)+IF(F38="X",2,0)+IF(G38="X",2,0)+IF(H38="X",3,IF(H38="Y",1.5,0))+IF(I38="X",5,IF(I38="Y",2.5,0))+IF(J38="X1",10,IF(J38="X2",5,IF(J38="X3",3,0))) -> 2 | N38: =+IF(K38="X",1,0) -> 0 | P38: =+L38/12 -> 0 | S38: Fuerza Popular | T38: Congresista
A39: =+A38+1 -> 3 | B39: 45209282 | C39: Renovación Popular | D39: X | E39: X | L39: 237928.72 | M39: =+IF(D39="X",1,0)+IF(E39="X",1,0)+IF(F39="X",2,0)+IF(G39="X",2,0)+IF(H39="X",3,IF(H39="Y",1.5,0))+IF(I39="X",5,IF(I39="Y",2.5,0))+IF(J39="X1",10,IF(J39="X2",5,IF(J39="X3",3,0))) -> 2 | N39: =+IF(K39="X",1,0) -> 0 | O39: 237928.72 | P39: =+L39/12 -> 19827.393 | Q39: =+O39/12 -> 19827.393 | R39: Renovación
A40: =+A39+1 -> 4 | B40: 25799622 | C40: Renovación Popular | D40: X | E40: X | H40: X | L40: 233142 | M40: =+IF(D40="X",1,0)+IF(E40="X",1,0)+IF(F40="X",2,0)+IF(G40="X",2,0)+IF(H40="X",3,IF(H40="Y",1.5,0))+IF(I40="X",5,IF(I40="Y",2.5,0))+IF(J40="X1",10,IF(J40="X2",5,IF(J40="X3",3,0))) -> 5 | N40: =+IF(K40="X",1,0) -> 0 | O40: 233142 | P40: =+L40/12 -> 19428.5 | Q40: =+O40/12 -> 19428.5 | U40: Jefa de Asesores - Congresistas
A41: =+A40+1 -> 5 | B41: 09376064 | C41: Renovación Popular | D41: X | E41: X | H41: X | I41: X | J41: X2 | K41: X | L41: 123028 | M41: =+IF(D41="X",1,0)+IF(E41="X",1,0)+IF(F41="X",2,0)+IF(G41="X",2,0)+IF(H41="X",3,IF(H41="Y",1.5,0))+IF(I41="X",5,IF(I41="Y",2.5,0))+IF(J41="X1",10,IF(J41="X2",5,IF(J41="X3",3,0))) -> 15 | N41: =+IF(K41="X",1,0) -> 1 | O41: 123028 | P41: =+L41/12 -> 10252.333 | Q41: =+O41/12 -> 10252.333 | S41: Peru 2000 | T41: Congresista
...

Sheet Resumen2
C1: Ingresos Mensuales Totales | G1: Preparación | I1: Sentencias | K1: Ingresos Mensuales Efectivos | N1: =1130*4 -> 4520
B2: Partido | C2: Promedio | D2: Desv. Standard | E2: # con Cero | F2: # Candidatos | G2: Promedio | H2: Desv. Standard | I2: Total | J2: Porcentaje | K2: Promedio | L2: Desv. Standard | M2: # Candidatos | N2: # Cand Efec
A3: 1 | B3: =INDIRECT(ADDRESS(34*(A3-1)+3,3,,,"Crudo2")) -> Ahora Nación | C3: =INDIRECT(ADDRESS(34*(A3-1)+33,16,,,"Crudo2")) -> 8509.7649 | D3: =INDIRECT(ADDRESS(34*(A3-1)+34,16,,,"Crudo2")) -> 8326.9528 | E3: =INDIRECT(ADDRESS(34*(A3-1)+35,12,,,"Crudo2")) -> 0 | F3: =+E3/M3 -> 0 | G3: =INDIRECT(ADDRESS(34*(A3-1)+33,13,,,"Crudo2")) -> 7.3928571 | H3: =INDIRECT(ADDRESS(34*(A3-1)+34,13,,,"Crudo2")) -> 4.7713597 | I3: =INDIRECT(ADDRESS(34*(A3-1)+33,14,,,"Crudo2")) -> 0 | J3: =+I3/M3 -> 0 | K3: =INDIRECT(ADDRESS(34*(A3-1)+33,17,,,"Crudo2")) -> 6872.4074 | L3: =INDIRECT(ADDRESS(34*(A3-1)+34,17,,,"Crudo2")) -> 5479.2327 | M3: =INDIRECT(ADDRESS(34*(A3-1)+35,13,,,"Crudo2")) -> 28 | N3: =+M3-E3 -> 28
A4: =+A3+1 -> 2 | B4: =INDIRECT(ADDRESS(34*(A4-1)+3,3,,,"Crudo2")) -> Renovación Popular | C4: =INDIRECT(ADDRESS(34*(A4-1)+33,16,,,"Crudo2")) -> 15310.844 | D4: =INDIRECT(ADDRESS(34*(A4-1)+34,16,,,"Crudo2")) -> 29497.025 | E4: =INDIRECT(ADDRESS(34*(A4-1)+35,12,,,"Crudo2")) -> 7 | F4: =+E4/M4 -> 0.24137931 | G4: =INDIRECT(ADDRESS(34*(A4-1)+33,13,,,"Crudo2")) -> 5.8275862 | H4: =INDIRECT(ADDRESS(34*(A4-1)+34,13,,,"Crudo2")) -> 3.6942906 | I4: =INDIRECT(ADDRESS(34*(A4-1)+33,14,,,"Crudo2")) -> 5 | J4: =+I4/M4 -> 0.17241379 | K4: =INDIRECT(ADDRESS(34*(A4-1)+33,17,,,"Crudo2")) -> 13614.285 | L4: =INDIRECT(ADDRESS(34*(A4-1)+34,17,,,"Crudo2")) -> 10648.482 | M4: =INDIRECT(ADDRESS(34*(A4-1)+35,13,,,"Crudo2")) -> 29 | N4: =+M4-E4 -> 22
A5: =+A4+1 -> 3 | B5: =INDIRECT(ADDRESS(34*(A5-1)+3,3,,,"Crudo2")) -> Fuerza Popular | C5: =INDIRECT(ADDRESS(34*(A5-1)+33,16,,,"Crudo2")) -> 16195.718 | D5: =INDIRECT(ADDRESS(34*(A5-1)+34,16,,,"Crudo2")) -> 14402.227 | E5: =INDIRECT(ADDRESS(34*(A5-1)+35,12,,,"Crudo2")) -> 1 | F5: =+E5/M5 -> 0.033333333 | G5: =INDIRECT(ADDRESS(34*(A5-1)+33,13,,,"Crudo2")) -> 6.8333333 | H5: =INDIRECT(ADDRESS(34*(A5-1)+34,13,,,"Crudo2")) -> 3.7608082 | I5: =INDIRECT(ADDRESS(34*(A5-1)+33,14,,,"Crudo2")) -> 6 | J5: =+I5/M5 -> 0.2 | K5: =INDIRECT(ADDRESS(34*(A5-1)+33,17,,,"Crudo2")) -> 15141.926 | L5: =INDIRECT(ADDRESS(34*(A5-1)+34,17,,,"Crudo2")) -> 10657.683 | M5: =INDIRECT(ADDRESS(34*(A5-1)+35,13,,,"Crudo2")) -> 30 | N5: =+M5-E5 -> 29
A6: =+A5+1 -> 4 | B6: =INDIRECT(ADDRESS(34*(A6-1)+3,3,,,"Crudo2")) -> Alianza para el Progreso | C6: =INDIRECT(ADDRESS(34*(A6-1)+33,16,,,"Crudo2")) -> 42399.07 | D6: =INDIRECT(ADDRESS(34*(A6-1)+34,16,,,"Crudo2")) -> 150040.03 | E6: =INDIRECT(ADDRESS(34*(A6-1)+35,12,,,"Crudo2")) -> 3 | F6: =+E6/M6 -> 0.10344828 | G6: =INDIRECT(ADDRESS(34*(A6-1)+33,13,,,"Crudo2")) -> 8.4137931 | H6: =INDIRECT(ADDRESS(34*(A6-1)+34,13,,,"Crudo2")) -> 4.9245539 | I6: =INDIRECT(ADDRESS(34*(A6-1)+33,14,,,"Crudo2")) -> 7 | J6: =+I6/M6 -> 0.24137931 | K6: =INDIRECT(ADDRESS(34*(A6-1)+33,17,,,"Crudo2")) -> 16393.701 | L6: =INDIRECT(ADDRESS(34*(A6-1)+34,17,,,"Crudo2")) -> 12570.068 | M6: =INDIRECT(ADDRESS(34*(A6-1)+35,13,,,"Crudo2")) -> 29 | N6: =+M6-E6 -> 26
A7: =+A6+1 -> 5 | B7: =INDIRECT(ADDRESS(34*(A7-1)+3,3,,,"Crudo2")) -> Juntos por el Perú | C7: =INDIRECT(ADDRESS(34*(A7-1)+33,16,,,"Crudo2")) -> 8226.7181 | D7: =INDIRECT(ADDRESS(34*(A7-1)+34,16,,,"Crudo2")) -> 16506.917 | E7: =INDIRECT(ADDRESS(34*(A7-1)+35,12,,,"Crudo2")) -> 8 | F7: =+E7/M7 -> 0.26666667 | G7: =INDIRECT(ADDRESS(34*(A7-1)+33,13,,,"Crudo2")) -> 5 | H7: =INDIRECT(ADDRESS(34*(A7-1)+34,13,,,"Crudo2")) -> 3.8506605 | I7: =INDIRECT(ADDRESS(34*(A7-1)+33,14,,,"Crudo2")) -> 2 | J7: =+I7/M7 -> 0.066666667 | K7: =INDIRECT(ADDRESS(34*(A7-1)+33,17,,,"Crudo2")) -> 7985.3433 | L7: =INDIRECT(ADDRESS(34*(A7-1)+34,17,,,"Crudo2")) -> 10804.794 | M7: =INDIRECT(ADDRESS(34*(A7-1)+35,13,,,"Crudo2")) -> 30 | N7: =+M7-E7 -> 22
A8: =+A7+1 -> 6 | B8: =INDIRECT(ADDRESS(34*(A8-1)+3,3,,,"Crudo2")) -> Buen Gobierno | C8: =INDIRECT(ADDRESS(34*(A8-1)+33,16,,,"Crudo2")) -> 6373.2589 | D8: =INDIRECT(ADDRESS(34*(A8-1)+34,16,,,"Crudo2")) -> 8562.9171 | E8: =INDIRECT(ADDRESS(34*(A8-1)+35,12,,,"Crudo2")) -> 2 | F8: =+E8/M8 -> 0.066666667 | G8: =INDIRECT(ADDRESS(34*(A8-1)+33,13,,,"Crudo2")) -> 6 | H8: =INDIRECT(ADDRESS(34*(A8-1)+34,13,,,"Crudo2")) -> 3.25894 | I8: =INDIRECT(ADDRESS(34*(A8-1)+33,14,,,"Crudo2")) -> 1 | J8: =+I8/M8 -> 0.033333333 | K8: =INDIRECT(ADDRESS(34*(A8-1)+33,17,,,"Crudo2")) -> 5266.158 | L8: =INDIRECT(ADDRESS(34*(A8-1)+34,17,,,"Crudo2")) -> 5446.8126 | M8: =INDIRECT(ADDRESS(34*(A8-1)+35,13,,,"Crudo2")) -> 30 | N8: =+M8-E8 -> 28
A9: =+A8+1 -> 7 | B9: =INDIRECT(ADDRESS(34*(A9-1)+3,3,,,"Crudo2")) -> Obras | C9: =INDIRECT(ADDRESS(34*(A9-1)+33,16,,,"Crudo2")) -> 2769.8314 | D9: =INDIRECT(ADDRESS(34*(A9-1)+34,16,,,"Crudo2")) -> 5039.9981 | E9: =INDIRECT(ADDRESS(34*(A9-1)+35,12,,,"Crudo2")) -> 9 | F9: =+E9/M9 -> 0.3 | G9: =INDIRECT(ADDRESS(34*(A9-1)+33,13,,,"Crudo2")) -> 3.7 | H9: =INDIRECT(ADDRESS(34*(A9-1)+34,13,,,"Crudo2")) -> 2.2916641 | I9: =INDIRECT(ADDRESS(34*(A9-1)+33,14,,,"Crudo2")) -> 2 | J9: =+I9/M9 -> 0.066666667 | K9: =INDIRECT(ADDRESS(34*(A9-1)+33,17,,,"Crudo2")) -> 3308.4868 | L9: =INDIRECT(ADDRESS(34*(A9-1)+34,17,,,"Crudo2")) -> 4320.5012 | M9: =INDIRECT(ADDRESS(34*(A9-1)+35,13,,,"Crudo2")) -> 30 | N9: =+M9-E9 -> 21
A10: =+A9+1 -> 8 | B10: Integridad Democrática | C10: =INDIRECT(ADDRESS(34*(A10-1)+33,16,,,"Crudo2")) -> 3869.726 | D10: =INDIRECT(ADDRESS(34*(A10-1)+34,16,,,"Crudo2")) -> 5453.1102 | E10: =INDIRECT(ADDRESS(34*(A10-1)+35,12,,,"Crudo2")) -> 14 | F10: =+E10/M10 -> 0.46666667 | G10: =INDIRECT(ADDRESS(34*(A10-1)+33,13,,,"Crudo2")) -> 7.4333333 | H10: =INDIRECT(ADDRESS(34*(A10-1)+34,13,,,"Crudo2")) -> 4.9527654 | I10: =INDIRECT(ADDRESS(34*(A10-1)+33,14,,,"Crudo2")) -> 0 | J10: =+I10/M10 -> 0 | K10: =INDIRECT(ADDRESS(34*(A10-1)+33,17,,,"Crudo2")) -> 6195.9687 | L10: =INDIRECT(ADDRESS(34*(A10-1)+34,17,,,"Crudo2")) -> 3777.0187 | M10: =INDIRECT(ADDRESS(34*(A10-1)+35,13,,,"Crudo2")) -> 30 | N10: =+M10-E10 -> 16
A11: =+A10+1 -> 9 | B11: =INDIRECT(ADDRESS(34*(A11-1)+3,3,,,"Crudo2")) -> Partido Morado | C11: =INDIRECT(ADDRESS(34*(A11-1)+33,16,,,"Crudo2")) -> 8654.1486 | D11: =INDIRECT(ADDRESS(34*(A11-1)+34,16,,,"Crudo2")) -> 10863.373 | E11: =INDIRECT(ADDRESS(34*(A11-1)+35,12,,,"Crudo2")) -> 1 | F11: =+E11/M11 -> 0.035714286 | G11: =INDIRECT(ADDRESS(34*(A11-1)+33,13,,,"Crudo2")) -> 6.3571429 | H11: =INDIRECT(ADDRESS(34*(A11-1)+34,13,,,"Crudo2")) -> 3.0455102 | I11: =INDIRECT(ADDRESS(34*(A11-1)+33,14,,,"Crudo2")) -> 2 | J11: =+I11/M11 -> 0.071428571 | K11: =INDIRECT(ADDRESS(34*(A11-1)+33,17,,,"Crudo2")) -> 6928.5959 | L11: =INDIRECT(ADDRESS(34*(A11-1)+34,17,,,"Crudo2")) -> 7778.2237 | M11: =INDIRECT(ADDRESS(34*(A11-1)+35,13,,,"Crudo2")) -> 28 | N11: =+M11-E11 -> 27
A12: =+A11+1 -> 10 | B12: =INDIRECT(ADDRESS(34*(A12-1)+3,3,,,"Crudo2")) -> Cooperación Popular | C12: =INDIRECT(ADDRESS(34*(A12-1)+33,16,,,"Crudo2")) -> 3355.8839 | D12: =INDIRECT(ADDRESS(34*(A12-1)+34,16,,,"Crudo2")) -> 6460.0595 | E12: =INDIRECT(ADDRESS(34*(A12-1)+35,12,,,"Crudo2")) -> 0 | F12: =+E12/M12 -> 0 | G12: =INDIRECT(ADDRESS(34*(A12-1)+33,13,,,"Crudo2")) -> 3.4285714 | H12: =INDIRECT(ADDRESS(34*(A12-1)+34,13,,,"Crudo2")) -> 3.2366944 | I12: =INDIRECT(ADDRESS(34*(A12-1)+33,14,,,"Crudo2")) -> 1 | J12: =+I12/M12 -> 0.035714286 | K12: =INDIRECT(ADDRESS(34*(A12-1)+33,17,,,"Crudo2")) -> 1885.5772 | L12: =INDIRECT(ADDRESS(34*(A12-1)+34,17,,,"Crudo2")) -> 1651.3348 | M12: =INDIRECT(ADDRESS(34*(A12-1)+35,13,,,"Crudo2")) -> 28 | N12: =+M12-E12 -> 28
A13: =+A12+1 -> 11 | B13: =INDIRECT(ADDRESS(34*(A13-1)+3,3,,,"Crudo2")) -> Unido Perú | C13: =INDIRECT(ADDRESS(34*(A13-1)+33,16,,,"Crudo2")) -> 4439.022 | D13: =INDIRECT(ADDRESS(34*(A13-1)+34,16,,,"Crudo2")) -> 3820.4286 | E13: =INDIRECT(ADDRESS(34*(A13-1)+35,12,,,"Crudo2")) -> 2 | F13: =+E13/M13 -> 0.11111111 | G13: =INDIRECT(ADDRESS(34*(A13-1)+33,13,,,"Crudo2")) -> 7.9444444 | H13: =INDIRECT(ADDRESS(34*(A13-1)+34,13,,,"Crudo2")) -> 5.3848614 | I13: =INDIRECT(ADDRESS(34*(A13-1)+33,14,,,"Crudo2")) -> 2 | J13: =+I13/M13 -> 0.11111111 | K13: =INDIRECT(ADDRESS(34*(A13-1)+33,17,,,"Crudo2")) -> 4105.0597 | L13: =INDIRECT(ADDRESS(34*(A13-1)+34,17,,,"Crudo2")) -> 2638.2567 | M13: =INDIRECT(ADDRESS(34*(A13-1)+35,13,,,"Crudo2")) -> 18 | N13: =+M13-E13 -> 16
A14: =+A13+1 -> 12 | B14: =INDIRECT(ADDRESS(34*(A14-1)+3,3,,,"Crudo2")) -> Pais para Todos | C14: =INDIRECT(ADDRESS(34*(A14-1)+33,16,,,"Crudo2")) -> 7261.4849 | D14: =INDIRECT(ADDRESS(34*(A14-1)+34,16,,,"Crudo2")) -> 10930.684 | E14: =INDIRECT(ADDRESS(34*(A14-1)+35,12,,,"Crudo2")) -> 5 | F14: =+E14/M14 -> 0.20833333 | G14: =INDIRECT(ADDRESS(34*(A14-1)+33,13,,,"Crudo2")) -> 7.9583333 | H14: =INDIRECT(ADDRESS(34*(A14-1)+34,13,,,"Crudo2")) -> 5.7519688 | I14: =INDIRECT(ADDRESS(34*(A14-1)+33,14,,,"Crudo2")) -> 1 | J14: =+I14/M14 -> 0.041666667 | K14: =INDIRECT(ADDRESS(34*(A14-1)+33,17,,,"Crudo2")) -> 7635.3224 | L14: =INDIRECT(ADDRESS(34*(A14-1)+34,17,,,"Crudo2")) -> 7237.4904 | M14: =INDIRECT(ADDRESS(34*(A14-1)+35,13,,,"Crudo2")) -> 24 | N14: =+M14-E14 -> 19
A15: =+A14+1 -> 13 | B15: =INDIRECT(ADDRESS(34*(A15-1)+3,3,,,"Crudo2")) -> Libertad Popular | C15: =INDIRECT(ADDRESS(34*(A15-1)+33,16,,,"Crudo2")) -> 9145.1448 | D15: =INDIRECT(ADDRESS(34*(A15-1)+34,16,,,"Crudo2")) -> 10920.548 | E15: =INDIRECT(ADDRESS(34*(A15-1)+35,12,,,"Crudo2")) -> 2 | F15: =+E15/M15 -> 0.074074074 | G15: =INDIRECT(ADDRESS(34*(A15-1)+33,13,,,"Crudo2")) -> 7.5185185 | H15: =INDIRECT(ADDRESS(34*(A15-1)+34,13,,,"Crudo2")) -> 5.4938453 | I15: =INDIRECT(ADDRESS(34*(A15-1)+33,14,,,"Crudo2")) -> 0 | J15: =+I15/M15 -> 0 | K15: =INDIRECT(ADDRESS(34*(A15-1)+33,17,,,"Crudo2")) -> 9840.3712 | L15: =INDIRECT(ADDRESS(34*(A15-1)+34,17,,,"Crudo2")) -> 11266.098 | M15: =INDIRECT(ADDRESS(34*(A15-1)+35,13,,,"Crudo2")) -> 27 | N15: =+M15-E15 -> 25
A16: =+A15+1 -> 14 | B16: =INDIRECT(ADDRESS(34*(A16-1)+3,3,,,"Crudo2")) -> Venceremos | C16: =INDIRECT(ADDRESS(34*(A16-1)+33,16,,,"Crudo2")) -> 7024.0844 | D16: =INDIRECT(ADDRESS(34*(A16-1)+34,16,,,"Crudo2")) -> 13559.356 | E16: =INDIRECT(ADDRESS(34*(A16-1)+35,12,,,"Crudo2")) -> 7 | F16: =+E16/M16 -> 0.25 | G16: =INDIRECT(ADDRESS(34*(A16-1)+33,13,,,"Crudo2")) -> 5.7142857 | H16: =INDIRECT(ADDRESS(34*(A16-1)+34,13,,,"Crudo2")) -> 3.8089285 | I16: =INDIRECT(ADDRESS(34*(A16-1)+33,14,,,"Crudo2")) -> 0 | J16: =+I16/M16 -> 0 | K16: =INDIRECT(ADDRESS(34*(A16-1)+33,17,,,"Crudo2")) -> 6629.4894 | L16: =INDIRECT(ADDRESS(34*(A16-1)+34,17,,,"Crudo2")) -> 8459.617 | M16: =INDIRECT(ADDRESS(34*(A16-1)+35,13,,,"Crudo2")) -> 28 | N16: =+M16-E16 -> 21
A17: =+A16+1 -> 15 | B17: =INDIRECT(ADDRESS(34*(A17-1)+3,3,,,"Crudo2")) -> Peru Primero | C17: =INDIRECT(ADDRESS(34*(A17-1)+33,16,,,"Crudo2")) -> 8740.4685 | D17: =INDIRECT(ADDRESS(34*(A17-1)+34,16,,,"Crudo2")) -> 9730.7656 | E17: =INDIRECT(ADDRESS(34*(A17-1)+35,12,,,"Crudo2")) -> 3 | F17: =+E17/M17 -> 0.10714286 | G17: =INDIRECT(ADDRESS(34*(A17-1)+33,13,,,"Crudo2")) -> 7.9285714 | H17: =INDIRECT(ADDRESS(34*(A17-1)+34,13,,,"Crudo2")) -> 3.8866207 | I17: =INDIRECT(ADDRESS(34*(A17-1)+33,14,,,"Crudo2")) -> 3 | J17: =+I17/M17 -> 0.10714286 | K17: =INDIRECT(ADDRESS(34*(A17-1)+33,17,,,"Crudo2")) -> 8821.5955 | L17: =INDIRECT(ADDRESS(34*(A17-1)+34,17,,,"Crudo2")) -> 8228.2428 | M17: =INDIRECT(ADDRESS(34*(A17-1)+35,13,,,"Crudo2")) -> 28 | N17: =+M17-E17 -> 25
A18: =+A17+1 -> 16 | B18: =INDIRECT(ADDRESS(34*(A18-1)+3,3,,,"Crudo2")) -> Primero La Gente | C18: =INDIRECT(ADDRESS(34*(A18-1)+33,16,,,"Crudo2")) -> 21686.198 | D18: =INDIRECT(ADDRESS(34*(A18-1)+34,16,,,"Crudo2")) -> 71085.079 | E18: =INDIRECT(ADDRESS(34*(A18-1)+35,12,,,"Crudo2")) -> 4 | F18: =+E18/M18 -> 0.14814815 | G18: =INDIRECT(ADDRESS(34*(A18-1)+33,13,,,"Crudo2")) -> 6.5555556 | H18: =INDIRECT(ADDRESS(34*(A18-1)+34,13,,,"Crudo2")) -> 3.1784531 | I18: =INDIRECT(ADDRESS(34*(A18-1)+33,14,,,"Crudo2")) -> 4 | J18: =+I18/M18 -> 0.14814815 | K18: =INDIRECT(ADDRESS(34*(A18-1)+33,17,,,"Crudo2")) -> 9599.9622 | L18: =INDIRECT(ADDRESS(34*(A18-1)+34,17,,,"Crudo2")) -> 8256.9106 | M18: =INDIRECT(ADDRESS(34*(A18-1)+35,13,,,"Crudo2")) -> 27 | N18: =+M18-E18 -> 23
A19: =+A18+1 -> 17 | B19: =INDIRECT(ADDRESS(34*(A19-1)+3,3,,,"Crudo2")) -> Fe en el Peru | C19: =INDIRECT(ADDRESS(34*(A19-1)+33,16,,,"Crudo2")) -> 4809.555 | D19: =INDIRECT(ADDRESS(34*(A19-1)+34,16,,,"Crudo2")) -> 4477.7625 | E19: =INDIRECT(ADDRESS(34*(A19-1)+35,12,,,"Crudo2")) -> 2 | F19: =+E19/M19 -> 0.11111111 | G19: =INDIRECT(ADDRESS(34*(A19-1)+33,13,,,"Crudo2")) -> 4.9333333 | H19: =INDIRECT(ADDRESS(34*(A19-1)+34,13,,,"Crudo2")) -> 3.8999389 | I19: =INDIRECT(ADDRESS(34*(A19-1)+33,14,,,"Crudo2")) -> 0 | J19: =+I19/M19 -> 0 | K19: =INDIRECT(ADDRESS(34*(A19-1)+33,17,,,"Crudo2")) -> 4705.0479 | L19: =INDIRECT(ADDRESS(34*(A19-1)+34,17,,,"Crudo2")) -> 3248.5512 | M19: =INDIRECT(ADDRESS(34*(A19-1)+35,13,,,"Crudo2")) -> 18 | N19: =+M19-E19 -> 16
A20: =+A19+1 -> 18 | B20: =INDIRECT(ADDRESS(34*(A20-1)+3,3,,,"Crudo2")) -> Avanza Pais | C20: =INDIRECT(ADDRESS(34*(A20-1)+33,16,,,"Crudo2")) -> 14076.754 | D20: =INDIRECT(ADDRESS(34*(A20-1)+34,16,,,"Crudo2")) -> 17844.18 | E20: =INDIRECT(ADDRESS(34*(A20-1)+35,12,,,"Crudo2")) -> 10 | F20: =+E20/M20 -> 0.4 | G20: =INDIRECT(ADDRESS(34*(A20-1)+33,13,,,"Crudo2")) -> 6.56 | H20: =INDIRECT(ADDRESS(34*(A20-1)+34,13,,,"Crudo2")) -> 4.5650849 | I20: =INDIRECT(ADDRESS(34*(A20-1)+33,14,,,"Crudo2")) -> 0 | J20: =+I20/M20 -> 0 | K20: =INDIRECT(ADDRESS(34*(A20-1)+33,17,,,"Crudo2")) -> 20119.151 | L20: =INDIRECT(ADDRESS(34*(A20-1)+34,17,,,"Crudo2")) -> 12384.043 | M20: =INDIRECT(ADDRESS(34*(A20-1)+35,13,,,"Crudo2")) -> 25 | N20: =+M20-E20 -> 15
A21: =+A20+1 -> 19 | B21: =INDIRECT(ADDRESS(34*(A21-1)+3,3,,,"Crudo2")) -> FREPAP | C21: =INDIRECT(ADDRESS(34*(A21-1)+33,16,,,"Crudo2")) -> 1215.609 | D21: =INDIRECT(ADDRESS(34*(A21-1)+34,16,,,"Crudo2")) -> 2435.3156 | E21: =INDIRECT(ADDRESS(34*(A21-1)+35,12,,,"Crudo2")) -> 22 | F21: =+E21/M21 -> 0.73333333 | G21: =INDIRECT(ADDRESS(34*(A21-1)+33,13,,,"Crudo2")) -> 3.9333333 | H21: =INDIRECT(ADDRESS(34*(A21-1)+34,13,,,"Crudo2")) -> 4.0337655 | I21: =INDIRECT(ADDRESS(34*(A21-1)+33,14,,,"Crudo2")) -> 0 | J21: =+I21/M21 -> 0 | K21: =INDIRECT(ADDRESS(34*(A21-1)+33,17,,,"Crudo2")) -> 3958.938 | L21: =INDIRECT(ADDRESS(34*(A21-1)+34,17,,,"Crudo2")) -> 2234.1509 | M21: =INDIRECT(ADDRESS(34*(A21-1)+35,13,,,"Crudo2")) -> 30 | N21: =+M21-E21 -> 8
A22: =+A21+1 -> 20 | B22: =INDIRECT(ADDRESS(34*(A22-1)+3,3,,,"Crudo2")) -> Fuerza y Libertad | C22: =INDIRECT(ADDRESS(34*(A22-1)+33,16,,,"Crudo2")) -> 6745.8043 | D22: =INDIRECT(ADDRESS(34*(A22-1)+34,16,,,"Crudo2")) -> 12148.142 | E22: =INDIRECT(ADDRESS(34*(A22-1)+35,12,,,"Crudo2")) -> 8 | F22: =+E22/M22 -> 0.28571429 | G22: =INDIRECT(ADDRESS(34*(A22-1)+33,13,,,"Crudo2")) -> 6.3571429 | H22: =INDIRECT(ADDRESS(34*(A22-1)+34,13,,,"Crudo2")) -> 5.2367242 | I22: =INDIRECT(ADDRESS(34*(A22-1)+33,14,,,"Crudo2")) -> 0 | J22: =+I22/M22 -> 0 | K22: =INDIRECT(ADDRESS(34*(A22-1)+33,17,,,"Crudo2")) -> 6684.74 | L22: =INDIRECT(ADDRESS(34*(A22-1)+34,17,,,"Crudo2")) -> 5683.9066 | M22: =INDIRECT(ADDRESS(34*(A22-1)+35,13,,,"Crudo2")) -> 28 | N22: =+M22-E22 -> 20
... A37: =+A36+1 -> 35 | B37: =INDIRECT(ADDRESS(34*(A37-1)+3,3,,,"Crudo2")) -> Peru Libre | C37: =INDIRECT(ADDRESS(34*(A37-1)+33,16,,,"Crudo2")) -> 12131.861 | D37: =INDIRECT(ADDRESS(34*(A37-1)+34,16,,,"Crudo2")) -> 12582.361 | E37: =INDIRECT(ADDRESS(34*(A37-1)+35,12,,,"Crudo2")) -> 1 | F37: =+E37/M37 -> 0.033333333 | G37: =INDIRECT(ADDRESS(34*(A37-1)+33,13,,,"Crudo2")) -> 6.4 | H37: =INDIRECT(ADDRESS(34*(A37-1)+34,13,,,"Crudo2")) -> 4.132295 | I37: =INDIRECT(ADDRESS(34*(A37-1)+33,14,,,"Crudo2")) -> 3 | J37: =+I37/M37 -> 0.1 | K37: =INDIRECT(ADDRESS(34*(A37-1)+33,17,,,"Crudo2")) -> 11726.846 | L37: =INDIRECT(ADDRESS(34*(A37-1)+34,17,,,"Crudo2")) -> 12000.673 | M37: =INDIRECT(ADDRESS(34*(A37-1)+35,13,,,"Crudo2")) -> 30 | N37: =+M37-E37 -> 29
A38: =+A37+1 -> 36 | B38: Salvemos al Perú
A39: =+A38+1 -> 37 | B39: Peru Moderno
A40: =+A39+1 -> 38 | B40: CPP

Sheet Op3
D2: =+C7/D7 -> 0.29 | F2: 5 | G2: =1130*4 -> 4520
C3: Sentencias | E3: Preparación | G3: Ingresos Mensuales Totales | I3: Ingresos Mensuales Efectivos
C4: Total | D4: Porcentaje | E4: Promedio | F4: Desv. Standard | G4: Promedio | H4: Desv. Standard | I4: Promedio | J4: Desv. Standard | K4: # con Cero | L4: # Candidatos | M4: # Candidatos | N4: # Cand Efec | O4: TK3
B5: Partido | C5: =+F5+1 -> 7 | D5: =+C5+1 -> 8 | E5: =+L5+1 -> 5 | F5: =+E5+1 -> 6 | G5: 1 | H5: =+G5+1 -> 2 | I5: =+D5+1 -> 9 | J5: =+I5+1 -> 10 | K5: =+H5+1 -> 3 | L5: =+K5+1 -> 4 | M5: =+J5+1 -> 11 | N5: =+M5+1 -> 12 | O5: =+N5+1 -> 13
A6: 1 | B6: Ahora Nación | C6: =+VLOOKUP($B6,Resumen2!$B:$N,'Op3'!C$5+1,FALSE) -> 0 | D6: =+VLOOKUP($B6,Resumen2!$B:$N,'Op3'!D$5+1,FALSE)*100 -> 0 | E6: =+VLOOKUP($B6,Resumen2!$B:$N,'Op3'!E$5+1,FALSE) -> 7.3928571 | F6: =+VLOOKUP($B6,Resumen2!$B:$N,'Op3'!F$5+1,FALSE) -> 4.7713597 | G6: =+VLOOKUP($B6,Resumen2!$B:$N,'Op3'!G$5+1,FALSE) -> 8509.7649 | H6: =+VLOOKUP($B6,Resumen2!$B:$N,'Op3'!H$5+1,FALSE) -> 8326.9528 | I6: =+VLOOKUP($B6,Resumen2!$B:$N,'Op3'!I$5+1,FALSE) -> 6872.4074 | J6: =+VLOOKUP($B6,Resumen2!$B:$N,'Op3'!J$5+1,FALSE) -> 5479.2327 | K6: =+VLOOKUP($B6,Resumen2!$B:$N,'Op3'!K$5+1,FALSE) -> 0 | L6: =+VLOOKUP($B6,Resumen2!$B:$N,'Op3'!L$5+1,FALSE) -> 0 | ... N6: =+VLOOKUP($B6,Resumen2!$B:$N,'Op3'!N$5+1,FALSE) -> 28 | O6: =+VLOOKUP($B6,Resumen!B:Q,16,FALSE) -> 0.27777778
A7: =+A6+1 -> 2 | B7: Alianza para el Progreso | C7: =+VLOOKUP($B7,Resumen2!$B:$N,'Op3'!C$5+1,FALSE) -> 7 | D7: =+VLOOKUP($B7,Resumen2!$B:$N,'Op3'!D$5+1,FALSE)*100 -> 24.137931 | E7: =+VLOOKUP($B7,Resumen2!$B:$N,'Op3'!E$5+1,FALSE) -> 8.4137931 | F7: =+VLOOKUP($B7,Resumen2!$B:$N,'Op3'!F$5+1,FALSE) -> 4.9245539 | G7: =+VLOOKUP($B7,Resumen2!$B:$N,'Op3'!G$5+1,FALSE) -> 42399.07 | H7: =+VLOOKUP($B7,Resumen2!$B:$N,'Op3'!H$5+1,FALSE) -> 150040.03 | I7: =+VLOOKUP($B7,Resumen2!$B:$N,'Op3'!I$5+1,FALSE) -> 16393.701 | J7: =+VLOOKUP($B7,Resumen2!$B:$N,'Op3'!J$5+1,FALSE) -> 12570.068 | K7: =+VLOOKUP($B7,Resumen2!$B:$N,'Op3'!K$5+1,FALSE) -> 3 | L7: =+VLOOKUP($B7,Resumen2!$B:$N,'Op3'!L$5+1,FALSE) -> 0.10344828 | ... N7: =+VLOOKUP($B7,Resumen2!$B:$N,'Op3'!N$5+1,FALSE) -> 26 | O7: =+VLOOKUP($B7,Resumen!B:Q,16,FALSE) -> 1
